//Schematic to java Structure by jajo_11 | inspired by "MITHION'S.SCHEMATIC TO JAVA CONVERTINGTOOL"

package com.hbm.world.dungeon;

import java.util.Random;

import com.hbm.blocks.ModBlocks;
import com.hbm.config.GeneralConfig;
import com.hbm.lib.HbmChestContents;
import com.hbm.lib.Library;
import com.hbm.tileentity.machine.storage.TileEntityMachinePuF6Tank;
import com.hbm.tileentity.machine.storage.TileEntityMachineUF6Tank;

import net.minecraft.block.Block;
import net.minecraft.init.Blocks;
import net.minecraft.item.ItemDoor;
import net.minecraft.tileentity.TileEntity;
import net.minecraft.tileentity.TileEntityChest;
import net.minecraft.util.WeightedRandomChestContent;
import net.minecraft.world.World;

public class DesertAtom003
{
	Block Block2 = ModBlocks.yellow_barrel;
	Block Block3 = ModBlocks.reinforced_sand;
	Block Block4 = ModBlocks.nuke_man;
	Block Block5 = ModBlocks.deco_steel;
	Block Block6 = ModBlocks.brick_light;
	Block Block7 = ModBlocks.deco_tungsten;
	Block Block8 = ModBlocks.steel_poles;
	Block Block9 = ModBlocks.tape_recorder;
	Block Block10 = ModBlocks.machine_nuke_furnace_off;
	Block Block11 = ModBlocks.reinforced_glass;
	Block Block12 = ModBlocks.reinforced_lamp_off;
	Block Block13 = ModBlocks.pole_satellite_receiver;
	Block Block14 = ModBlocks.machine_generator;
	Block Block15 = ModBlocks.deco_titanium;
	Block Block16 = ModBlocks.block_lead;
	Block Block17 = ModBlocks.ore_schrabidium;
	Block Block18 = ModBlocks.waste_planks;
	Block Block19 = ModBlocks.machine_centrifuge;
	Block Block20 = ModBlocks.machine_uf6_tank;
	Block Block21 = ModBlocks.machine_puf6_tank;
	Block Block22 = ModBlocks.reinforced_brick;
	Block Block23 = ModBlocks.waste_earth;
	Block Block24 = ModBlocks.deco_lead;
	Block Block25 = ModBlocks.red_wire_coated;
	Block Block26 = ModBlocks.block_uranium;
	Block Block27 = ModBlocks.pole_top;
	Block Block28 = ModBlocks.machine_battery;
	Block Block29 = ModBlocks.machine_electric_furnace_off;
	
	public boolean generate_r00(World world, Random rand, int x, int y, int z)
    {
		world.setBlock(x + 21, y + 3, z + 12, this.Block6, 0, 3);
		world.setBlock(x + 22, y + 3, z + 12, this.Block6, 0, 3);
		world.setBlock(x + 23, y + 3, z + 12, this.Block6, 0, 3);
		world.setBlock(x + 24, y + 3, z + 12, this.Block6, 0, 3);
		world.setBlock(x + 25, y + 3, z + 12, this.Block6, 0, 3);
		world.setBlock(x + 26, y + 3, z + 12, this.Block6, 0, 3);
		world.setBlock(x + 27, y + 3, z + 12, this.Block6, 0, 3);
		world.setBlock(x + 28, y + 3, z + 12, this.Block6, 0, 3);
		world.setBlock(x + 29, y + 3, z + 12, this.Block6, 0, 3);
		world.setBlock(x + 30, y + 3, z + 12, this.Block6, 0, 3);
		world.setBlock(x + 31, y + 3, z + 12, this.Block6, 0, 3);
		world.setBlock(x + 32, y + 3, z + 12, this.Block6, 0, 3);
		world.setBlock(x + 33, y + 3, z + 12, this.Block6, 0, 3);
		world.setBlock(x + 34, y + 3, z + 12, this.Block6, 0, 3);
		world.setBlock(x + 35, y + 3, z + 12, this.Block6, 0, 3);
		world.setBlock(x + 36, y + 3, z + 12, this.Block18, 0, 3);
		world.setBlock(x + 37, y + 3, z + 12, Library.getRandomConcrete(), 0, 3);
		world.setBlock(x + 40, y + 3, z + 12, ModBlocks.barbed_wire, 0, 3);
		world.setBlock(x + 0, y + 3, z + 13, ModBlocks.barbed_wire, 0, 3);
		world.setBlock(x + 4, y + 3, z + 13, this.Block5, 0, 3);
		world.setBlock(x + 5, y + 3, z + 13, this.Block5, 0, 3);
		world.setBlock(x + 6, y + 3, z + 13, Blocks.water, 0, 3);
		world.setBlock(x + 7, y + 3, z + 13, this.Block16, 4, 3);
		world.setBlock(x + 8, y + 3, z + 13, this.Block14, 0, 3);
		world.setBlock(x + 9, y + 3, z + 13, this.Block16, 2, 3);
		world.setBlock(x + 10, y + 3, z + 13, Blocks.water, 0, 3);
		world.setBlock(x + 11, y + 3, z + 13, this.Block5, 0, 3);
		world.setBlock(x + 12, y + 3, z + 13, this.Block5, 0, 3);
		world.setBlock(x + 16, y + 3, z + 13, Library.getRandomConcrete(), 0, 3);
		world.setBlock(x + 19, y + 3, z + 13, this.Block6, 0, 3);
		world.setBlock(x + 20, y + 3, z + 13, this.Block6, 0, 3);
		world.setBlock(x + 21, y + 3, z + 13, this.Block6, 0, 3);
		world.setBlock(x + 22, y + 3, z + 13, this.Block6, 0, 3);
		world.setBlock(x + 23, y + 3, z + 13, this.Block6, 0, 3);
		world.setBlock(x + 24, y + 3, z + 13, this.Block6, 0, 3);
		world.setBlock(x + 25, y + 3, z + 13, this.Block6, 0, 3);
		world.setBlock(x + 26, y + 3, z + 13, this.Block6, 0, 3);
		world.setBlock(x + 27, y + 3, z + 13, this.Block6, 0, 3);
		world.setBlock(x + 28, y + 3, z + 13, this.Block6, 0, 3);
		world.setBlock(x + 29, y + 3, z + 13, this.Block6, 0, 3);
		world.setBlock(x + 30, y + 3, z + 13, this.Block6, 0, 3);
		world.setBlock(x + 31, y + 3, z + 13, this.Block6, 0, 3);
		world.setBlock(x + 32, y + 3, z + 13, this.Block6, 0, 3);
		world.setBlock(x + 33, y + 3, z + 13, this.Block6, 0, 3);
		world.setBlock(x + 34, y + 3, z + 13, this.Block18, 0, 3);
		world.setBlock(x + 35, y + 3, z + 13, this.Block18, 0, 3);
		world.setBlock(x + 36, y + 3, z + 13, this.Block18, 0, 3);
		world.setBlock(x + 37, y + 3, z + 13, Library.getRandomConcrete(), 0, 3);
		world.setBlock(x + 40, y + 3, z + 13, ModBlocks.barbed_wire, 0, 3);
		world.setBlock(x + 0, y + 3, z + 14, ModBlocks.barbed_wire, 0, 3);
		world.setBlock(x + 4, y + 3, z + 14, this.Block5, 0, 3);
		world.setBlock(x + 5, y + 3, z + 14, this.Block5, 0, 3);
		world.setBlock(x + 6, y + 3, z + 14, this.Block5, 0, 3);
		world.setBlock(x + 7, y + 3, z + 14, Blocks.water, 0, 3);
		world.setBlock(x + 8, y + 3, z + 14, this.Block5, 0, 3);
		world.setBlock(x + 9, y + 3, z + 14, Blocks.water, 0, 3);
		world.setBlock(x + 10, y + 3, z + 14, this.Block5, 0, 3);
		world.setBlock(x + 11, y + 3, z + 14, this.Block5, 0, 3);
		world.setBlock(x + 12, y + 3, z + 14, this.Block5, 0, 3);
		world.setBlock(x + 16, y + 3, z + 14, Library.getRandomConcrete(), 0, 3);
		world.setBlock(x + 17, y + 3, z + 14, Blocks.vine, 2, 3);
		world.setBlock(x + 19, y + 3, z + 14, this.Block6, 0, 3);
		world.setBlock(x + 20, y + 3, z + 14, this.Block6, 0, 3);
		world.setBlock(x + 21, y + 3, z + 14, this.Block6, 0, 3);
		world.setBlock(x + 22, y + 3, z + 14, this.Block6, 0, 3);
		world.setBlock(x + 23, y + 3, z + 14, this.Block6, 0, 3);
		world.setBlock(x + 24, y + 3, z + 14, this.Block6, 0, 3);
		world.setBlock(x + 25, y + 3, z + 14, this.Block6, 0, 3);
		world.setBlock(x + 26, y + 3, z + 14, this.Block6, 0, 3);
		world.setBlock(x + 27, y + 3, z + 14, this.Block6, 0, 3);
		world.setBlock(x + 28, y + 3, z + 14, this.Block6, 0, 3);
		world.setBlock(x + 29, y + 3, z + 14, this.Block6, 0, 3);
		world.setBlock(x + 30, y + 3, z + 14, this.Block6, 0, 3);
		world.setBlock(x + 31, y + 3, z + 14, this.Block6, 0, 3);
		world.setBlock(x + 32, y + 3, z + 14, this.Block6, 0, 3);
		world.setBlock(x + 33, y + 3, z + 14, this.Block18, 0, 3);
		world.setBlock(x + 34, y + 3, z + 14, this.Block18, 0, 3);
		world.setBlock(x + 35, y + 3, z + 14, this.Block18, 0, 3);
		world.setBlock(x + 36, y + 3, z + 14, this.Block18, 0, 3);
		world.setBlock(x + 37, y + 3, z + 14, Library.getRandomConcrete(), 0, 3);
		world.setBlock(x + 40, y + 3, z + 14, ModBlocks.barbed_wire, 0, 3);
		world.setBlock(x + 0, y + 3, z + 15, ModBlocks.barbed_wire, 0, 3);
		world.setBlock(x + 5, y + 3, z + 15, this.Block5, 0, 3);
		world.setBlock(x + 6, y + 3, z + 15, this.Block5, 0, 3);
		world.setBlock(x + 7, y + 3, z + 15, this.Block5, 0, 3);
		world.setBlock(x + 8, y + 3, z + 15, this.Block5, 0, 3);
		world.setBlock(x + 9, y + 3, z + 15, this.Block5, 0, 3);
		world.setBlock(x + 10, y + 3, z + 15, this.Block5, 0, 3);
		world.setBlock(x + 11, y + 3, z + 15, this.Block5, 0, 3);
		world.setBlock(x + 16, y + 3, z + 15, Library.getRandomConcrete(), 0, 3);
		world.setBlock(x + 17, y + 3, z + 15, Blocks.stone_stairs, 2, 3);
		world.setBlock(x + 18, y + 3, z + 15, Blocks.stone_stairs, 2, 3);
		world.setBlock(x + 19, y + 3, z + 15, this.Block6, 0, 3);
		world.setBlock(x + 20, y + 3, z + 15, this.Block6, 0, 3);
		world.setBlock(x + 21, y + 3, z + 15, this.Block6, 0, 3);
		world.setBlock(x + 22, y + 3, z + 15, this.Block6, 0, 3);
		world.setBlock(x + 23, y + 3, z + 15, this.Block6, 0, 3);
		world.setBlock(x + 24, y + 3, z + 15, this.Block6, 0, 3);
		world.setBlock(x + 25, y + 3, z + 15, this.Block6, 0, 3);
		world.setBlock(x + 26, y + 3, z + 15, this.Block6, 0, 3);
		world.setBlock(x + 27, y + 3, z + 15, this.Block6, 0, 3);
		world.setBlock(x + 28, y + 3, z + 15, this.Block6, 0, 3);
		world.setBlock(x + 29, y + 3, z + 15, this.Block6, 0, 3);
		world.setBlock(x + 30, y + 3, z + 15, this.Block6, 0, 3);
		world.setBlock(x + 31, y + 3, z + 15, this.Block6, 0, 3);
		world.setBlock(x + 32, y + 3, z + 15, this.Block18, 0, 3);
		world.setBlock(x + 33, y + 3, z + 15, this.Block18, 0, 3);
		world.setBlock(x + 34, y + 3, z + 15, this.Block18, 0, 3);
		world.setBlock(x + 35, y + 3, z + 15, this.Block18, 0, 3);
		world.setBlock(x + 37, y + 3, z + 15, Library.getRandomConcrete(), 0, 3);
		world.setBlock(x + 40, y + 3, z + 15, ModBlocks.barbed_wire, 0, 3);
		world.setBlock(x + 0, y + 3, z + 16, ModBlocks.barbed_wire, 0, 3);
		world.setBlock(x + 6, y + 3, z + 16, this.Block5, 0, 3);
		world.setBlock(x + 7, y + 3, z + 16, this.Block5, 0, 3);
		world.setBlock(x + 8, y + 3, z + 16, this.Block5, 0, 3);
		world.setBlock(x + 9, y + 3, z + 16, this.Block5, 0, 3);
		world.setBlock(x + 10, y + 3, z + 16, this.Block5, 0, 3);
		world.setBlock(x + 16, y + 3, z + 16, Library.getRandomConcrete(), 0, 3);
		world.setBlock(x + 17, y + 3, z + 16, this.Block6, 0, 3);
		world.setBlock(x + 18, y + 3, z + 16, this.Block6, 0, 3);
		world.setBlock(x + 19, y + 3, z + 16, this.Block6, 0, 3);
		world.setBlock(x + 20, y + 3, z + 16, this.Block6, 0, 3);
		world.setBlock(x + 21, y + 3, z + 16, this.Block6, 0, 3);
		world.setBlock(x + 22, y + 3, z + 16, this.Block6, 0, 3);
		world.setBlock(x + 23, y + 3, z + 16, this.Block6, 0, 3);
		world.setBlock(x + 24, y + 3, z + 16, this.Block6, 0, 3);
		world.setBlock(x + 25, y + 3, z + 16, this.Block6, 0, 3);
		world.setBlock(x + 26, y + 3, z + 16, this.Block6, 0, 3);
		world.setBlock(x + 27, y + 3, z + 16, this.Block6, 0, 3);
		world.setBlock(x + 28, y + 3, z + 16, this.Block6, 0, 3);
		world.setBlock(x + 29, y + 3, z + 16, this.Block6, 0, 3);
		world.setBlock(x + 30, y + 3, z + 16, this.Block6, 0, 3);
		world.setBlock(x + 31, y + 3, z + 16, this.Block6, 0, 3);
		world.setBlock(x + 32, y + 3, z + 16, this.Block18, 0, 3);
		world.setBlock(x + 33, y + 3, z + 16, this.Block18, 0, 3);
		world.setBlock(x + 34, y + 3, z + 16, Blocks.vine, 4, 3);
		world.setBlock(x + 37, y + 3, z + 16, Library.getRandomConcrete(), 0, 3);
		world.setBlock(x + 40, y + 3, z + 16, ModBlocks.barbed_wire, 0, 3);
		world.setBlock(x + 0, y + 3, z + 17, ModBlocks.barbed_wire, 0, 3);
		world.setBlock(x + 16, y + 3, z + 17, Library.getRandomConcrete(), 0, 3);
		world.setBlock(x + 17, y + 3, z + 17, this.Block6, 0, 3);
		world.setBlock(x + 18, y + 3, z + 17, this.Block6, 0, 3);
		world.setBlock(x + 19, y + 3, z + 17, this.Block6, 0, 3);
		world.setBlock(x + 20, y + 3, z + 17, this.Block6, 0, 3);
		world.setBlock(x + 21, y + 3, z + 17, this.Block6, 0, 3);
		world.setBlock(x + 22, y + 3, z + 17, this.Block6, 0, 3);
		world.setBlock(x + 23, y + 3, z + 17, this.Block6, 0, 3);
		world.setBlock(x + 24, y + 3, z + 17, this.Block6, 0, 3);
		world.setBlock(x + 25, y + 3, z + 17, this.Block6, 0, 3);
		world.setBlock(x + 26, y + 3, z + 17, this.Block6, 0, 3);
		world.setBlock(x + 27, y + 3, z + 17, this.Block6, 0, 3);
		world.setBlock(x + 28, y + 3, z + 17, this.Block6, 0, 3);
		world.setBlock(x + 29, y + 3, z + 17, this.Block6, 0, 3);
		world.setBlock(x + 30, y + 3, z + 17, this.Block6, 0, 3);
		world.setBlock(x + 31, y + 3, z + 17, this.Block6, 0, 3);
		world.setBlock(x + 32, y + 3, z + 17, this.Block18, 0, 3);
		world.setBlock(x + 33, y + 3, z + 17, this.Block18, 0, 3);
		world.setBlock(x + 34, y + 3, z + 17, this.Block18, 0, 3);
		world.setBlock(x + 35, y + 3, z + 17, Blocks.vine, 2, 3);
		world.setBlock(x + 40, y + 3, z + 17, ModBlocks.barbed_wire, 0, 3);
		world.setBlock(x + 0, y + 3, z + 18, ModBlocks.barbed_wire, 0, 3);
		world.setBlock(x + 16, y + 3, z + 18, Library.getRandomConcrete(), 0, 3);
		world.setBlock(x + 17, y + 3, z + 18, Library.getRandomConcrete(), 0, 3);
		world.setBlock(x + 18, y + 3, z + 18, Library.getRandomConcrete(), 0, 3);
		world.setBlock(x + 19, y + 3, z + 18, Library.getRandomConcrete(), 0, 3);
		world.setBlock(x + 20, y + 3, z + 18, Library.getRandomConcrete(), 0, 3);
		world.setBlock(x + 21, y + 3, z + 18, Library.getRandomConcrete(), 0, 3);
		world.setBlock(x + 22, y + 3, z + 18, Library.getRandomConcrete(), 0, 3);
		world.setBlock(x + 23, y + 3, z + 18, Library.getRandomConcrete(), 0, 3);
		world.setBlock(x + 24, y + 3, z + 18, Library.getRandomConcrete(), 0, 3);
		world.setBlock(x + 25, y + 3, z + 18, Library.getRandomConcrete(), 0, 3);
		world.setBlock(x + 26, y + 3, z + 18, Library.getRandomConcrete(), 0, 3);
		world.setBlock(x + 27, y + 3, z + 18, Library.getRandomConcrete(), 0, 3);
		world.setBlock(x + 28, y + 3, z + 18, Library.getRandomConcrete(), 0, 3);
		world.setBlock(x + 29, y + 3, z + 18, Library.getRandomConcrete(), 0, 3);
		world.setBlock(x + 30, y + 3, z + 18, Library.getRandomConcrete(), 0, 3);
		world.setBlock(x + 31, y + 3, z + 18, Library.getRandomConcrete(), 0, 3);
		world.setBlock(x + 32, y + 3, z + 18, Library.getRandomConcrete(), 0, 3);
		world.setBlock(x + 33, y + 3, z + 18, Library.getRandomConcrete(), 0, 3);
		world.setBlock(x + 34, y + 3, z + 18, Library.getRandomConcrete(), 0, 3);
		world.setBlock(x + 35, y + 3, z + 18, Blocks.gravel, 0, 3);
		world.setBlock(x + 36, y + 3, z + 18, Blocks.gravel, 0, 3);
		world.setBlock(x + 40, y + 3, z + 18, ModBlocks.barbed_wire, 0, 3);
		world.setBlock(x + 0, y + 3, z + 19, ModBlocks.barbed_wire, 0, 3);
		world.setBlock(x + 40, y + 3, z + 19, ModBlocks.barbed_wire, 0, 3);
		world.setBlock(x + 0, y + 3, z + 20, ModBlocks.barbed_wire, 0, 3);
		world.setBlock(x + 6, y + 3, z + 20, this.Block15, 0, 3);
		world.setBlock(x + 7, y + 3, z + 20, this.Block15, 0, 3);
		world.setBlock(x + 8, y + 3, z + 20, this.Block15, 0, 3);
		world.setBlock(x + 9, y + 3, z + 20, this.Block15, 0, 3);
		world.setBlock(x + 10, y + 3, z + 20, this.Block15, 0, 3);
		world.setBlock(x + 40, y + 3, z + 20, ModBlocks.barbed_wire, 0, 3);
		world.setBlock(x + 0, y + 3, z + 21, ModBlocks.barbed_wire, 0, 3);
		world.setBlock(x + 4, y + 3, z + 21, this.Block15, 0, 3);
		world.setBlock(x + 5, y + 3, z + 21, this.Block15, 0, 3);
		world.setBlock(x + 11, y + 3, z + 21, this.Block15, 0, 3);
		world.setBlock(x + 12, y + 3, z + 21, this.Block15, 0, 3);
		world.setBlock(x + 40, y + 3, z + 21, ModBlocks.barbed_wire, 0, 3);
		world.setBlock(x + 0, y + 3, z + 22, ModBlocks.barbed_wire, 0, 3);
		world.setBlock(x + 4, y + 3, z + 22, this.Block15, 0, 3);
		world.setBlock(x + 12, y + 3, z + 22, this.Block15, 0, 3);
		world.setBlock(x + 40, y + 3, z + 22, ModBlocks.barbed_wire, 0, 3);
		world.setBlock(x + 0, y + 3, z + 23, ModBlocks.barbed_wire, 0, 3);
		world.setBlock(x + 3, y + 3, z + 23, this.Block15, 0, 3);
		world.setBlock(x + 13, y + 3, z + 23, this.Block15, 0, 3);
		world.setBlock(x + 40, y + 3, z + 23, ModBlocks.barbed_wire, 0, 3);
		world.setBlock(x + 0, y + 3, z + 24, ModBlocks.barbed_wire, 0, 3);
		world.setBlock(x + 3, y + 3, z + 24, this.Block15, 0, 3);
		world.setBlock(x + 13, y + 3, z + 24, this.Block15, 0, 3);
		world.setBlock(x + 40, y + 3, z + 24, ModBlocks.barbed_wire, 0, 3);
		world.setBlock(x + 0, y + 3, z + 25, ModBlocks.barbed_wire, 0, 3);
		world.setBlock(x + 3, y + 3, z + 25, this.Block15, 0, 3);
		world.setBlock(x + 13, y + 3, z + 25, this.Block15, 0, 3);
		world.setBlock(x + 40, y + 3, z + 25, ModBlocks.barbed_wire, 0, 3);
		world.setBlock(x + 0, y + 3, z + 26, ModBlocks.barbed_wire, 0, 3);
		world.setBlock(x + 3, y + 3, z + 26, this.Block15, 0, 3);
		world.setBlock(x + 13, y + 3, z + 26, this.Block15, 0, 3);
		world.setBlock(x + 40, y + 3, z + 26, ModBlocks.barbed_wire, 0, 3);
		world.setBlock(x + 0, y + 3, z + 27, ModBlocks.barbed_wire, 0, 3);
		world.setBlock(x + 3, y + 3, z + 27, this.Block15, 0, 3);
		world.setBlock(x + 13, y + 3, z + 27, this.Block15, 0, 3);
		world.setBlock(x + 40, y + 3, z + 27, ModBlocks.barbed_wire, 0, 3);
		world.setBlock(x + 0, y + 3, z + 28, ModBlocks.barbed_wire, 0, 3);
		world.setBlock(x + 4, y + 3, z + 28, this.Block15, 0, 3);
		world.setBlock(x + 12, y + 3, z + 28, this.Block15, 0, 3);
		world.setBlock(x + 40, y + 3, z + 28, ModBlocks.barbed_wire, 0, 3);
		world.setBlock(x + 0, y + 3, z + 29, ModBlocks.barbed_wire, 0, 3);
		world.setBlock(x + 4, y + 3, z + 29, this.Block15, 0, 3);
		world.setBlock(x + 5, y + 3, z + 29, this.Block15, 0, 3);
		world.setBlock(x + 11, y + 3, z + 29, this.Block15, 0, 3);
		world.setBlock(x + 12, y + 3, z + 29, this.Block15, 0, 3);
		world.setBlock(x + 40, y + 3, z + 29, ModBlocks.barbed_wire, 0, 3);
		world.setBlock(x + 0, y + 3, z + 30, ModBlocks.barbed_wire, 0, 3);
		world.setBlock(x + 6, y + 3, z + 30, this.Block15, 0, 3);
		world.setBlock(x + 7, y + 3, z + 30, this.Block15, 0, 3);
		world.setBlock(x + 8, y + 3, z + 30, this.Block15, 0, 3);
		world.setBlock(x + 9, y + 3, z + 30, this.Block15, 0, 3);
		world.setBlock(x + 10, y + 3, z + 30, this.Block15, 0, 3);
		world.setBlock(x + 40, y + 3, z + 30, ModBlocks.barbed_wire, 0, 3);
		world.setBlock(x + 0, y + 3, z + 31, ModBlocks.barbed_wire, 0, 3);
		world.setBlock(x + 16, y + 3, z + 31, this.Block5, 0, 3);
		world.setBlock(x + 17, y + 3, z + 31, ModBlocks.barbed_wire, 0, 3);
		world.setBlock(x + 18, y + 3, z + 31, ModBlocks.barbed_wire, 0, 3);
		world.setBlock(x + 19, y + 3, z + 31, ModBlocks.barbed_wire, 0, 3);
		world.setBlock(x + 20, y + 3, z + 31, ModBlocks.barbed_wire, 0, 3);
		world.setBlock(x + 21, y + 3, z + 31, ModBlocks.barbed_wire, 0, 3);
		world.setBlock(x + 22, y + 3, z + 31, ModBlocks.barbed_wire, 0, 3);
		world.setBlock(x + 23, y + 3, z + 31, ModBlocks.barbed_wire, 0, 3);
		world.setBlock(x + 24, y + 3, z + 31, ModBlocks.barbed_wire, 0, 3);
		world.setBlock(x + 25, y + 3, z + 31, ModBlocks.barbed_wire, 0, 3);
		world.setBlock(x + 26, y + 3, z + 31, ModBlocks.barbed_wire, 0, 3);
		world.setBlock(x + 27, y + 3, z + 31, ModBlocks.barbed_wire, 0, 3);
		world.setBlock(x + 28, y + 3, z + 31, ModBlocks.barbed_wire, 0, 3);
		world.setBlock(x + 29, y + 3, z + 31, ModBlocks.barbed_wire, 0, 3);
		world.setBlock(x + 30, y + 3, z + 31, ModBlocks.barbed_wire, 0, 3);
		world.setBlock(x + 31, y + 3, z + 31, ModBlocks.barbed_wire, 0, 3);
		world.setBlock(x + 32, y + 3, z + 31, ModBlocks.barbed_wire, 0, 3);
		world.setBlock(x + 33, y + 3, z + 31, ModBlocks.barbed_wire, 0, 3);
		world.setBlock(x + 34, y + 3, z + 31, ModBlocks.barbed_wire, 0, 3);
		world.setBlock(x + 35, y + 3, z + 31, ModBlocks.barbed_wire, 0, 3);
		world.setBlock(x + 36, y + 3, z + 31, ModBlocks.barbed_wire, 0, 3);
		world.setBlock(x + 37, y + 3, z + 31, ModBlocks.barbed_wire, 0, 3);
		world.setBlock(x + 38, y + 3, z + 31, ModBlocks.barbed_wire, 0, 3);
		world.setBlock(x + 39, y + 3, z + 31, ModBlocks.barbed_wire, 0, 3);
		world.setBlock(x + 40, y + 3, z + 31, this.Block5, 0, 3);
		world.setBlock(x + 0, y + 3, z + 32, ModBlocks.barbed_wire, 0, 3);
		world.setBlock(x + 16, y + 3, z + 32, ModBlocks.barbed_wire, 0, 3);
		world.setBlock(x + 0, y + 3, z + 33, this.Block5, 0, 3);
		world.setBlock(x + 1, y + 3, z + 33, ModBlocks.barbed_wire, 0, 3);
		world.setBlock(x + 2, y + 3, z + 33, ModBlocks.barbed_wire, 0, 3);
		world.setBlock(x + 3, y + 3, z + 33, ModBlocks.barbed_wire, 0, 3);
		world.setBlock(x + 4, y + 3, z + 33, ModBlocks.barbed_wire, 0, 3);
		world.setBlock(x + 5, y + 3, z + 33, ModBlocks.barbed_wire, 0, 3);
		world.setBlock(x + 6, y + 3, z + 33, ModBlocks.barbed_wire, 0, 3);
		world.setBlock(x + 7, y + 3, z + 33, ModBlocks.barbed_wire, 0, 3);
		world.setBlock(x + 8, y + 3, z + 33, ModBlocks.barbed_wire, 0, 3);
		world.setBlock(x + 9, y + 3, z + 33, ModBlocks.barbed_wire, 0, 3);
		world.setBlock(x + 10, y + 3, z + 33, ModBlocks.barbed_wire, 0, 3);
		world.setBlock(x + 11, y + 3, z + 33, ModBlocks.barbed_wire, 0, 3);
		world.setBlock(x + 12, y + 3, z + 33, ModBlocks.barbed_wire, 0, 3);
		world.setBlock(x + 13, y + 3, z + 33, ModBlocks.barbed_wire, 0, 3);
		world.setBlock(x + 14, y + 3, z + 33, ModBlocks.barbed_wire, 0, 3);
		world.setBlock(x + 15, y + 3, z + 33, ModBlocks.barbed_wire, 0, 3);
		world.setBlock(x + 16, y + 3, z + 33, this.Block5, 0, 3);
		world.setBlock(x + 16, y + 4, z + 6, Library.getRandomConcrete(), 0, 3);
		world.setBlock(x + 17, y + 4, z + 6, Library.getRandomConcrete(), 0, 3);
		world.setBlock(x + 18, y + 4, z + 6, Library.getRandomConcrete(), 0, 3);
		world.setBlock(x + 19, y + 4, z + 6, Library.getRandomConcrete(), 0, 3);
		world.setBlock(x + 20, y + 4, z + 6, Library.getRandomConcrete(), 0, 3);
		world.setBlock(x + 21, y + 4, z + 6, Library.getRandomConcrete(), 0, 3);
		world.setBlock(x + 22, y + 4, z + 6, Library.getRandomConcrete(), 0, 3);
		world.setBlock(x + 23, y + 4, z + 6, Library.getRandomConcrete(), 0, 3);
		world.setBlock(x + 24, y + 4, z + 6, Library.getRandomConcrete(), 0, 3);
		world.setBlock(x + 25, y + 4, z + 6, Library.getRandomConcrete(), 0, 3);
		world.setBlock(x + 26, y + 4, z + 6, Library.getRandomConcrete(), 0, 3);
		world.setBlock(x + 27, y + 4, z + 6, Library.getRandomConcrete(), 0, 3);
		world.setBlock(x + 28, y + 4, z + 6, Library.getRandomConcrete(), 0, 3);
		world.setBlock(x + 29, y + 4, z + 6, Library.getRandomConcrete(), 0, 3);
		world.setBlock(x + 30, y + 4, z + 6, Library.getRandomConcrete(), 0, 3);
		world.setBlock(x + 31, y + 4, z + 6, Library.getRandomConcrete(), 0, 3);
		world.setBlock(x + 32, y + 4, z + 6, Library.getRandomConcrete(), 0, 3);
		world.setBlock(x + 33, y + 4, z + 6, Library.getRandomConcrete(), 0, 3);
		world.setBlock(x + 34, y + 4, z + 6, Library.getRandomConcrete(), 0, 3);
		world.setBlock(x + 35, y + 4, z + 6, Library.getRandomConcrete(), 0, 3);
		world.setBlock(x + 36, y + 4, z + 6, Library.getRandomConcrete(), 0, 3);
		world.setBlock(x + 37, y + 4, z + 6, Library.getRandomConcrete(), 0, 3);
		world.setBlock(x + 7, y + 4, z + 7, this.Block8, 2, 3);
		world.setBlock(x + 9, y + 4, z + 7, this.Block8, 2, 3);
		world.setBlock(x + 16, y + 4, z + 7, Library.getRandomConcrete(), 0, 3);
		world.setBlock(x + 18, y + 4, z + 7, Blocks.vine, 4, 3);
		world.setBlock(x + 19, y + 4, z + 7, Blocks.vine, 4, 3);
		world.setBlock(x + 20, y + 4, z + 7, Blocks.vine, 4, 3);
		world.setBlock(x + 23, y + 4, z + 7, Library.getRandomConcrete(), 0, 3);
		world.setBlock(x + 25, y + 4, z + 7, this.Block8, 3, 3);
		world.setBlock(x + 26, y + 4, z + 7, this.Block19, 12, 3);
		world.setBlock(x + 27, y + 4, z + 7, this.Block19, 12, 3);
		world.setBlock(x + 28, y + 4, z + 7, this.Block20, 3, 3);
		TileEntity tank0 = world.getTileEntity(x + 28, y + 4, z + 7);
		if(tank0 instanceof TileEntityMachineUF6Tank)
		{
		}
		world.setBlock(x + 29, y + 4, z + 7, this.Block20, 3, 3);
		world.getTileEntity(x + 29, y + 4, z + 7);
		if(tank0 instanceof TileEntityMachineUF6Tank)
		{
		}
		world.setBlock(x + 30, y + 4, z + 7, this.Block21, 3, 3);
		world.getTileEntity(x + 30, y + 4, z + 7);
		if(tank0 instanceof TileEntityMachinePuF6Tank)
		{
		}
		world.setBlock(x + 31, y + 4, z + 7, this.Block21, 3, 3);
		TileEntity tank3 = world.getTileEntity(x + 31, y + 4, z + 7);
		if(tank3 instanceof TileEntityMachinePuF6Tank)
		{
		}
		world.setBlock(x + 32, y + 4, z + 7, this.Block2, 0, 3);
		world.setBlock(x + 33, y + 4, z + 7, this.Block22, 0, 3);
		world.setBlock(x + 34, y + 4, z + 7, this.Block23, 0, 3);
		world.setBlock(x + 35, y + 4, z + 7, this.Block23, 0, 3);
		world.setBlock(x + 36, y + 4, z + 7, this.Block23, 0, 3);
		world.setBlock(x + 37, y + 4, z + 7, Library.getRandomConcrete(), 0, 3);
		world.setBlock(x + 40, y + 4, z + 7, this.Block5, 0, 3);
		world.setBlock(x + 6, y + 4, z + 8, this.Block5, 0, 3);
		world.setBlock(x + 7, y + 4, z + 8, this.Block5, 0, 3);
		//world.setBlock(x + 8, y + 4, z + 8, Blocks.iron_door, 1, 3);
        ItemDoor.placeDoorBlock(world, x + 8, y + 4, z + 8, 1, Blocks.iron_door);
		world.setBlock(x + 9, y + 4, z + 8, this.Block5, 0, 3);
		world.setBlock(x + 10, y + 4, z + 8, this.Block5, 0, 3);
		world.setBlock(x + 16, y + 4, z + 8, Library.getRandomConcrete(), 0, 3);
		world.setBlock(x + 19, y + 4, z + 8, ModBlocks.fence_metal, 0, 3);
		world.setBlock(x + 23, y + 4, z + 8, Library.getRandomConcrete(), 0, 3);
		world.setBlock(x + 24, y + 4, z + 8, this.Block12, 0, 3);
		world.setBlock(x + 26, y + 4, z + 8, Blocks.unpowered_repeater, 0, 3);
		world.setBlock(x + 27, y + 4, z + 8, Blocks.unpowered_repeater, 0, 3);
		world.setBlock(x + 31, y + 4, z + 8, Blocks.unpowered_repeater, 0, 3);
		world.setBlock(x + 32, y + 4, z + 8, this.Block2, 0, 3);
		world.setBlock(x + 33, y + 4, z + 8, this.Block22, 0, 3);
		world.setBlock(x + 34, y + 4, z + 8, this.Block22, 0, 3);
		world.setBlock(x + 35, y + 4, z + 8, this.Block22, 0, 3);
		world.setBlock(x + 36, y + 4, z + 8, this.Block22, 0, 3);
		world.setBlock(x + 37, y + 4, z + 8, Library.getRandomConcrete(), 0, 3);
		world.setBlock(x + 40, y + 4, z + 8, this.Block5, 0, 3);
		world.setBlock(x + 5, y + 4, z + 9, this.Block5, 0, 3);
		world.setBlock(x + 6, y + 4, z + 9, this.Block2, 0, 3);
		world.setBlock(x + 7, y + 4, z + 9, this.Block2, 0, 3);
		world.setBlock(x + 10, y + 4, z + 9, this.Block2, 0, 3);
		world.setBlock(x + 11, y + 4, z + 9, this.Block5, 0, 3);
		world.setBlock(x + 16, y + 4, z + 9, Library.getRandomConcrete(), 0, 3);
		world.setBlock(x + 17, y + 4, z + 9, Blocks.stone_stairs, 2, 3);
		world.setBlock(x + 18, y + 4, z + 9, Blocks.stone_stairs, 2, 3);
		world.setBlock(x + 19, y + 4, z + 9, ModBlocks.fence_metal, 0, 3);
		world.setBlock(x + 23, y + 4, z + 9, Library.getRandomConcrete(), 0, 3);
		world.setBlock(x + 24, y + 4, z + 9, Blocks.redstone_wire, 0, 3);
		world.setBlock(x + 26, y + 4, z + 9, Blocks.redstone_wire, 0, 3);
		world.setBlock(x + 27, y + 4, z + 9, Blocks.redstone_wire, 0, 3);
		world.setBlock(x + 28, y + 4, z + 9, Blocks.redstone_wire, 0, 3);
		world.setBlock(x + 30, y + 4, z + 9, Blocks.redstone_wire, 0, 3);
		world.setBlock(x + 31, y + 4, z + 9, Blocks.redstone_wire, 0, 3);
		world.setBlock(x + 32, y + 4, z + 9, Blocks.unpowered_repeater, 1, 3);
		world.setBlock(x + 33, y + 4, z + 9, Blocks.redstone_wire, 0, 3);
		world.setBlock(x + 34, y + 4, z + 9, Blocks.redstone_wire, 0, 3);
		world.setBlock(x + 35, y + 4, z + 9, this.Block12, 0, 3);
		world.setBlock(x + 35, y + 5, z + 9, ModBlocks.geiger, 2, 3);
		world.setBlock(x + 36, y + 4, z + 9, Blocks.chest, 2, 3);
		if(world.getBlock(x + 36, y + 4, z + 9) == Blocks.chest)
		{
			WeightedRandomChestContent.generateChestContents(rand, HbmChestContents.nuclear, (TileEntityChest)world.getTileEntity(x + 36, y + 4, z + 9), 12);
		}
        world.setBlock(x + 37, y + 4, z + 9, Library.getRandomConcrete(), 0, 3);
		world.setBlock(x + 40, y + 4, z + 9, this.Block5, 0, 3);
		world.setBlock(x + 4, y + 4, z + 10, this.Block5, 0, 3);
		world.setBlock(x + 5, y + 4, z + 10, this.Block2, 0, 3);
		world.setBlock(x + 11, y + 4, z + 10, this.Block2, 0, 3);
		world.setBlock(x + 12, y + 4, z + 10, this.Block5, 0, 3);
		world.setBlock(x + 16, y + 4, z + 10, Library.getRandomConcrete(), 0, 3);
		world.setBlock(x + 17, y + 4, z + 10, Blocks.stone_stairs, 7, 3);
		world.setBlock(x + 18, y + 4, z + 10, Blocks.stone_stairs, 7, 3);
		world.setBlock(x + 19, y + 4, z + 10, ModBlocks.fence_metal, 0, 3);
		world.setBlock(x + 20, y + 4, z + 10, Blocks.web, 0, 3);
		world.setBlock(x + 23, y + 4, z + 10, Library.getRandomConcrete(), 0, 3);
		world.setBlock(x + 24, y + 4, z + 10, Blocks.redstone_wire, 0, 3);
		world.setBlock(x + 25, y + 4, z + 10, Blocks.redstone_wire, 0, 3);
		world.setBlock(x + 26, y + 4, z + 10, Blocks.redstone_wire, 0, 3);
		world.setBlock(x + 28, y + 4, z + 10, Blocks.redstone_wire, 0, 3);
		world.setBlock(x + 29, y + 4, z + 10, Blocks.redstone_wire, 0, 3);
		world.setBlock(x + 30, y + 4, z + 10, Blocks.redstone_wire, 0, 3);
		world.setBlock(x + 35, y + 4, z + 10, Blocks.redstone_wire, 0, 3);
		world.setBlock(x + 37, y + 4, z + 10, Library.getRandomConcrete(), 0, 3);
		world.setBlock(x + 40, y + 4, z + 10, this.Block5, 0, 3);
		world.setBlock(x + 4, y + 4, z + 11, this.Block5, 0, 3);
		world.setBlock(x + 5, y + 4, z + 11, this.Block2, 0, 3);
		world.setBlock(x + 11, y + 4, z + 11, this.Block2, 0, 3);
		world.setBlock(x + 12, y + 4, z + 11, this.Block5, 0, 3);
		world.setBlock(x + 16, y + 4, z + 11, Library.getRandomConcrete(), 0, 3);
		world.setBlock(x + 22, y + 4, z + 11, Blocks.vine, 8, 3);
		world.setBlock(x + 23, y + 4, z + 11, Library.getRandomConcrete(), 0, 3);
		world.setBlock(x + 24, y + 4, z + 11, Blocks.redstone_wire, 0, 3);
		world.setBlock(x + 27, y + 4, z + 11, Blocks.redstone_wire, 0, 3);
		world.setBlock(x + 28, y + 4, z + 11, this.Block24, 0, 3);
		world.setBlock(x + 29, y + 4, z + 11, this.Block24, 0, 3);
		world.setBlock(x + 30, y + 4, z + 11, this.Block24, 0, 3);
		world.setBlock(x + 34, y + 4, z + 11, Blocks.redstone_wire, 0, 3);
		world.setBlock(x + 37, y + 4, z + 11, Library.getRandomConcrete(), 0, 3);
		world.setBlock(x + 4, y + 4, z + 12, this.Block5, 0, 3);
		world.setBlock(x + 8, y + 4, z + 12, this.Block14, 0, 3);
		world.setBlock(x + 11, y + 4, z + 12, this.Block2, 0, 3);
		world.setBlock(x + 12, y + 4, z + 12, this.Block5, 0, 3);
		world.setBlock(x + 16, y + 4, z + 12, Library.getRandomConcrete(), 0, 3);
		world.setBlock(x + 19, y + 4, z + 12, ModBlocks.fence_metal, 0, 3);
		world.setBlock(x + 22, y + 4, z + 12, Blocks.vine, 8, 3);
		world.setBlock(x + 23, y + 4, z + 12, Library.getRandomConcrete(), 0, 3);
		world.setBlock(x + 24, y + 4, z + 12, Blocks.redstone_wire, 0, 3);
		world.setBlock(x + 27, y + 4, z + 12, Blocks.vine, 8, 3);
		world.setBlock(x + 28, y + 4, z + 12, this.Block24, 0, 3);
		world.setBlock(x + 29, y + 4, z + 12, this.Block24, 0, 3);
		world.setBlock(x + 30, y + 4, z + 12, this.Block24, 0, 3);
		world.setBlock(x + 31, y + 4, z + 12, Blocks.vine, 2, 3);
		world.setBlock(x + 32, y + 4, z + 12, Blocks.redstone_wire, 0, 3);
		world.setBlock(x + 36, y + 4, z + 12, Blocks.vine, 8, 3);
		world.setBlock(x + 37, y + 4, z + 12, Library.getRandomConcrete(), 0, 3);
		world.setBlock(x + 4, y + 4, z + 13, this.Block5, 0, 3);
		world.setBlock(x + 5, y + 4, z + 13, this.Block2, 0, 3);
		world.setBlock(x + 12, y + 4, z + 13, this.Block5, 0, 3);
		world.setBlock(x + 16, y + 4, z + 13, Library.getRandomConcrete(), 0, 3);
		world.setBlock(x + 17, y + 4, z + 13, Blocks.vine, 2, 3);
		world.setBlock(x + 19, y + 4, z + 13, ModBlocks.fence_metal, 0, 3);
		world.setBlock(x + 22, y + 4, z + 13, Blocks.vine, 8, 3);
		world.setBlock(x + 23, y + 4, z + 13, Library.getRandomConcrete(), 0, 3);
		world.setBlock(x + 24, y + 4, z + 13, Blocks.redstone_wire, 0, 3);
		world.setBlock(x + 25, y + 4, z + 13, Blocks.redstone_wire, 0, 3);
		world.setBlock(x + 26, y + 4, z + 13, Blocks.redstone_wire, 0, 3);
		world.setBlock(x + 28, y + 4, z + 13, this.Block24, 0, 3);
		world.setBlock(x + 29, y + 4, z + 13, this.Block24, 0, 3);
		world.setBlock(x + 30, y + 4, z + 13, this.Block24, 0, 3);
		world.setBlock(x + 31, y + 4, z + 13, Blocks.web, 0, 3);
		world.setBlock(x + 36, y + 4, z + 13, Blocks.vine, 8, 3);
		world.setBlock(x + 37, y + 4, z + 13, Library.getRandomConcrete(), 0, 3);
		world.setBlock(x + 4, y + 4, z + 14, this.Block5, 0, 3);
		world.setBlock(x + 12, y + 4, z + 14, this.Block5, 0, 3);
		world.setBlock(x + 16, y + 4, z + 14, Library.getRandomConcrete(), 0, 3);
		world.setBlock(x + 17, y + 4, z + 14, Blocks.vine, 2, 3);
		world.setBlock(x + 19, y + 4, z + 14, ModBlocks.fence_metal, 0, 3);
		world.setBlock(x + 23, y + 4, z + 14, Library.getRandomConcrete(), 0, 3);
		world.setBlock(x + 24, y + 4, z + 14, this.Block12, 0, 3);
		world.setBlock(x + 26, y + 4, z + 14, Blocks.redstone_wire, 0, 3);
		world.setBlock(x + 27, y + 4, z + 14, Blocks.redstone_wire, 0, 3);
		world.setBlock(x + 28, y + 4, z + 14, Blocks.redstone_wire, 0, 3);
		world.setBlock(x + 29, y + 4, z + 14, this.Block25, 0, 3);
		world.setBlock(x + 30, y + 4, z + 14, Blocks.web, 0, 3);
		world.setBlock(x + 31, y + 4, z + 14, Blocks.redstone_wire, 0, 3);
		world.setBlock(x + 37, y + 4, z + 14, Library.getRandomConcrete(), 0, 3);
		world.setBlock(x + 5, y + 4, z + 15, this.Block5, 0, 3);
		world.setBlock(x + 8, y + 4, z + 15, this.Block2, 0, 3);
		world.setBlock(x + 9, y + 4, z + 15, this.Block2, 0, 3);
		world.setBlock(x + 10, y + 4, z + 15, this.Block2, 0, 3);
		world.setBlock(x + 11, y + 4, z + 15, this.Block5, 0, 3);
		world.setBlock(x + 16, y + 4, z + 15, Library.getRandomConcrete(), 0, 3);
		world.setBlock(x + 19, y + 4, z + 15, ModBlocks.fence_metal, 0, 3);
		world.setBlock(x + 23, y + 4, z + 15, Blocks.iron_door, 0, 3);
        ItemDoor.placeDoorBlock(world, x + 23, y + 4, z + 15, 0, Blocks.iron_door);
		world.setBlock(x + 24, y + 4, z + 15, Blocks.vine, 2, 3);
		world.setBlock(x + 27, y + 4, z + 15, Blocks.redstone_wire, 0, 3);
		world.setBlock(x + 30, y + 4, z + 15, Blocks.redstone_wire, 0, 3);
		world.setBlock(x + 31, y + 4, z + 15, Blocks.redstone_wire, 0, 3);
		world.setBlock(x + 37, y + 4, z + 15, Library.getRandomConcrete(), 0, 3);
		world.setBlock(x + 6, y + 4, z + 16, this.Block5, 0, 3);
		world.setBlock(x + 7, y + 4, z + 16, this.Block5, 0, 3);
		world.setBlock(x + 8, y + 4, z + 16, this.Block5, 0, 3);
		world.setBlock(x + 9, y + 4, z + 16, this.Block5, 0, 3);
		world.setBlock(x + 10, y + 4, z + 16, this.Block5, 0, 3);
		world.setBlock(x + 16, y + 4, z + 16, Library.getRandomConcrete(), 0, 3);
		world.setBlock(x + 22, y + 4, z + 16, Blocks.vine, 8, 3);
		//world.setBlock(x + 23, y + 4, z + 16, Blocks.iron_door, 3, 3);
        ItemDoor.placeDoorBlock(world, x + 23, y + 4, z + 16, 3, Blocks.iron_door);
		world.setBlock(x + 26, y + 4, z + 16, Blocks.redstone_wire, 0, 3);
		world.setBlock(x + 29, y + 4, z + 16, Blocks.unpowered_repeater, 2, 3);
		world.setBlock(x + 37, y + 4, z + 16, Blocks.gravel, 0, 3);
		world.setBlock(x + 16, y + 4, z + 17, Library.getRandomConcrete(), 0, 3);
		world.setBlock(x + 21, y + 4, z + 17, Blocks.vine, 1, 3);
		world.setBlock(x + 22, y + 4, z + 17, Blocks.vine, 8, 3);
		world.setBlock(x + 23, y + 4, z + 17, Library.getRandomConcrete(), 0, 3);
		world.setBlock(x + 27, y + 4, z + 17, Blocks.vine, 1, 3);
		world.setBlock(x + 28, y + 4, z + 17, Blocks.vine, 9, 3);
		world.setBlock(x + 29, y + 4, z + 17, this.Block12, 0, 3);
		world.setBlock(x + 33, y + 4, z + 17, Blocks.vine, 3, 3);
		world.setBlock(x + 16, y + 4, z + 18, Library.getRandomConcrete(), 0, 3);
		world.setBlock(x + 17, y + 4, z + 18, Library.getRandomConcrete(), 0, 3);
		world.setBlock(x + 18, y + 4, z + 18, Library.getRandomConcrete(), 0, 3);
		world.setBlock(x + 19, y + 4, z + 18, Library.getRandomConcrete(), 0, 3);
		world.setBlock(x + 20, y + 4, z + 18, Library.getRandomConcrete(), 0, 3);
		world.setBlock(x + 21, y + 4, z + 18, Library.getRandomConcrete(), 0, 3);
		world.setBlock(x + 22, y + 4, z + 18, Library.getRandomConcrete(), 0, 3);
		world.setBlock(x + 23, y + 4, z + 18, Library.getRandomConcrete(), 0, 3);
		world.setBlock(x + 24, y + 4, z + 18, Library.getRandomConcrete(), 0, 3);
		world.setBlock(x + 25, y + 4, z + 18, Library.getRandomConcrete(), 0, 3);
		world.setBlock(x + 26, y + 4, z + 18, Library.getRandomConcrete(), 0, 3);
		world.setBlock(x + 27, y + 4, z + 18, Library.getRandomConcrete(), 0, 3);
		world.setBlock(x + 28, y + 4, z + 18, Library.getRandomConcrete(), 0, 3);
		world.setBlock(x + 29, y + 4, z + 18, Library.getRandomConcrete(), 0, 3);
		world.setBlock(x + 30, y + 4, z + 18, Library.getRandomConcrete(), 0, 3);
		world.setBlock(x + 31, y + 4, z + 18, Library.getRandomConcrete(), 0, 3);
		world.setBlock(x + 32, y + 4, z + 18, Library.getRandomConcrete(), 0, 3);
		world.setBlock(x + 33, y + 4, z + 18, Library.getRandomConcrete(), 0, 3);
		world.setBlock(x + 34, y + 4, z + 18, Library.getRandomConcrete(), 0, 3);
		world.setBlock(x + 6, y + 4, z + 20, this.Block15, 0, 3);
		world.setBlock(x + 7, y + 4, z + 20, this.Block15, 0, 3);
		world.setBlock(x + 8, y + 4, z + 20, this.Block15, 0, 3);
		world.setBlock(x + 9, y + 4, z + 20, this.Block15, 0, 3);
		world.setBlock(x + 10, y + 4, z + 20, this.Block15, 0, 3);
		world.setBlock(x + 4, y + 4, z + 21, this.Block15, 0, 3);
		world.setBlock(x + 5, y + 4, z + 21, this.Block15, 0, 3);
		world.setBlock(x + 6, y + 4, z + 21, this.Block7, 0, 3);
		world.setBlock(x + 7, y + 4, z + 21, this.Block7, 0, 3);
		world.setBlock(x + 8, y + 4, z + 21, this.Block7, 0, 3);
		world.setBlock(x + 9, y + 4, z + 21, this.Block7, 0, 3);
		world.setBlock(x + 10, y + 4, z + 21, this.Block7, 0, 3);
		world.setBlock(x + 11, y + 4, z + 21, this.Block15, 0, 3);
		world.setBlock(x + 12, y + 4, z + 21, this.Block15, 0, 3);
		world.setBlock(x + 4, y + 4, z + 22, this.Block15, 0, 3);
		world.setBlock(x + 5, y + 4, z + 22, this.Block7, 0, 3);
		world.setBlock(x + 11, y + 4, z + 22, this.Block7, 0, 3);
		world.setBlock(x + 12, y + 4, z + 22, this.Block15, 0, 3);
		world.setBlock(x + 3, y + 4, z + 23, this.Block15, 0, 3);
		world.setBlock(x + 4, y + 4, z + 23, this.Block7, 0, 3);
		world.setBlock(x + 12, y + 4, z + 23, this.Block7, 0, 3);
		world.setBlock(x + 13, y + 4, z + 23, this.Block15, 0, 3);
		world.setBlock(x + 3, y + 4, z + 24, this.Block15, 0, 3);
		world.setBlock(x + 4, y + 4, z + 24, this.Block7, 0, 3);
		world.setBlock(x + 12, y + 4, z + 24, this.Block7, 0, 3);
		world.setBlock(x + 13, y + 4, z + 24, this.Block15, 0, 3);
		world.setBlock(x + 3, y + 4, z + 25, this.Block15, 0, 3);
		world.setBlock(x + 4, y + 4, z + 25, this.Block7, 0, 3);
		world.setBlock(x + 12, y + 4, z + 25, this.Block7, 0, 3);
		world.setBlock(x + 13, y + 4, z + 25, this.Block15, 0, 3);
		world.setBlock(x + 3, y + 4, z + 26, this.Block15, 0, 3);
		world.setBlock(x + 4, y + 4, z + 26, this.Block7, 0, 3);
		world.setBlock(x + 12, y + 4, z + 26, this.Block7, 0, 3);
		world.setBlock(x + 13, y + 4, z + 26, this.Block15, 0, 3);
		world.setBlock(x + 3, y + 4, z + 27, this.Block15, 0, 3);
		world.setBlock(x + 4, y + 4, z + 27, this.Block7, 0, 3);
		world.setBlock(x + 12, y + 4, z + 27, this.Block7, 0, 3);
		world.setBlock(x + 13, y + 4, z + 27, this.Block15, 0, 3);
		world.setBlock(x + 4, y + 4, z + 28, this.Block15, 0, 3);
		world.setBlock(x + 5, y + 4, z + 28, this.Block7, 0, 3);
		world.setBlock(x + 11, y + 4, z + 28, this.Block7, 0, 3);
		world.setBlock(x + 12, y + 4, z + 28, this.Block15, 0, 3);
		world.setBlock(x + 4, y + 4, z + 29, this.Block15, 0, 3);
		world.setBlock(x + 5, y + 4, z + 29, this.Block15, 0, 3);
		world.setBlock(x + 6, y + 4, z + 29, this.Block7, 0, 3);
		world.setBlock(x + 7, y + 4, z + 29, this.Block7, 0, 3);
		world.setBlock(x + 8, y + 4, z + 29, this.Block7, 0, 3);
		world.setBlock(x + 9, y + 4, z + 29, this.Block7, 0, 3);
		world.setBlock(x + 10, y + 4, z + 29, this.Block7, 0, 3);
		world.setBlock(x + 11, y + 4, z + 29, this.Block15, 0, 3);
		world.setBlock(x + 12, y + 4, z + 29, this.Block15, 0, 3);
		world.setBlock(x + 6, y + 4, z + 30, this.Block15, 0, 3);
		world.setBlock(x + 7, y + 4, z + 30, this.Block15, 0, 3);
		world.setBlock(x + 8, y + 4, z + 30, this.Block15, 0, 3);
		world.setBlock(x + 9, y + 4, z + 30, this.Block15, 0, 3);
		world.setBlock(x + 10, y + 4, z + 30, this.Block15, 0, 3);
		world.setBlock(x + 16, y + 5, z + 6, Library.getRandomConcrete(), 0, 3);
		world.setBlock(x + 17, y + 5, z + 6, Library.getRandomConcrete(), 0, 3);
		world.setBlock(x + 18, y + 5, z + 6, this.Block11, 0, 3);
		world.setBlock(x + 19, y + 5, z + 6, this.Block11, 0, 3);
		world.setBlock(x + 20, y + 5, z + 6, Library.getRandomConcrete(), 0, 3);
		world.setBlock(x + 21, y + 5, z + 6, Library.getRandomConcrete(), 0, 3);
		world.setBlock(x + 22, y + 5, z + 6, Library.getRandomConcrete(), 0, 3);
		world.setBlock(x + 23, y + 5, z + 6, Library.getRandomConcrete(), 0, 3);
		world.setBlock(x + 24, y + 5, z + 6, Library.getRandomConcrete(), 0, 3);
		world.setBlock(x + 25, y + 5, z + 6, Library.getRandomConcrete(), 0, 3);
		world.setBlock(x + 26, y + 5, z + 6, Library.getRandomConcrete(), 0, 3);
		world.setBlock(x + 27, y + 5, z + 6, Library.getRandomConcrete(), 0, 3);
		world.setBlock(x + 28, y + 5, z + 6, Library.getRandomConcrete(), 0, 3);
		world.setBlock(x + 29, y + 5, z + 6, Library.getRandomConcrete(), 0, 3);
		world.setBlock(x + 30, y + 5, z + 6, Library.getRandomConcrete(), 0, 3);
		world.setBlock(x + 31, y + 5, z + 6, Library.getRandomConcrete(), 0, 3);
		world.setBlock(x + 32, y + 5, z + 6, Library.getRandomConcrete(), 0, 3);
		world.setBlock(x + 33, y + 5, z + 6, Library.getRandomConcrete(), 0, 3);
		world.setBlock(x + 34, y + 5, z + 6, Library.getRandomConcrete(), 0, 3);
		world.setBlock(x + 35, y + 5, z + 6, Library.getRandomConcrete(), 0, 3);
		world.setBlock(x + 36, y + 5, z + 6, Library.getRandomConcrete(), 0, 3);
		world.setBlock(x + 37, y + 5, z + 6, Library.getRandomConcrete(), 0, 3);
		world.setBlock(x + 7, y + 5, z + 7, this.Block8, 2, 3);
		world.setBlock(x + 9, y + 5, z + 7, this.Block8, 2, 3);
		world.setBlock(x + 16, y + 5, z + 7, Library.getRandomConcrete(), 0, 3);
		world.setBlock(x + 18, y + 5, z + 7, Blocks.vine, 4, 3);
		world.setBlock(x + 19, y + 5, z + 7, Blocks.vine, 4, 3);
		world.setBlock(x + 20, y + 5, z + 7, Blocks.vine, 4, 3);
		world.setBlock(x + 22, y + 5, z + 7, Blocks.web, 0, 3);
		world.setBlock(x + 23, y + 5, z + 7, Library.getRandomConcrete(), 0, 3);
		world.setBlock(x + 25, y + 5, z + 7, this.Block8, 3, 3);
		world.setBlock(x + 30, y + 5, z + 7, Blocks.vine, 4, 3);
		world.setBlock(x + 32, y + 5, z + 7, this.Block2, 0, 3);
		world.setBlock(x + 33, y + 5, z + 7, this.Block11, 0, 3);
		world.setBlock(x + 37, y + 5, z + 7, Library.getRandomConcrete(), 0, 3);
		world.setBlock(x + 6, y + 5, z + 8, this.Block5, 0, 3);
		world.setBlock(x + 7, y + 5, z + 8, this.Block5, 0, 3);
		//world.setBlock(x + 8, y + 5, z + 8, Blocks.iron_door, 8, 3);
		world.setBlock(x + 9, y + 5, z + 8, this.Block5, 0, 3);
		world.setBlock(x + 10, y + 5, z + 8, this.Block5, 0, 3);
		world.setBlock(x + 16, y + 5, z + 8, this.Block11, 0, 3);
		world.setBlock(x + 23, y + 5, z + 8, this.Block11, 0, 3);
		world.setBlock(x + 33, y + 5, z + 8, this.Block11, 0, 3);
		world.setBlock(x + 34, y + 5, z + 8, this.Block11, 0, 3);
		world.setBlock(x + 35, y + 5, z + 8, this.Block11, 0, 3);
		world.setBlock(x + 36, y + 5, z + 8, this.Block11, 0, 3);
		world.setBlock(x + 37, y + 5, z + 8, Library.getRandomConcrete(), 0, 3);
		world.setBlock(x + 5, y + 5, z + 9, this.Block5, 0, 3);
		world.setBlock(x + 11, y + 5, z + 9, this.Block5, 0, 3);
		world.setBlock(x + 16, y + 5, z + 9, this.Block11, 0, 3);
		world.setBlock(x + 19, y + 5, z + 9, ModBlocks.fence_metal, 0, 3);
		world.setBlock(x + 23, y + 5, z + 9, this.Block11, 0, 3);
		world.setBlock(x + 33, y + 5, z + 9, Blocks.vine, 4, 3);
		world.setBlock(x + 37, y + 5, z + 9, Library.getRandomConcrete(), 0, 3);
		world.setBlock(x + 4, y + 5, z + 10, this.Block5, 0, 3);
		world.setBlock(x + 12, y + 5, z + 10, this.Block5, 0, 3);
		world.setBlock(x + 16, y + 5, z + 10, Library.getRandomConcrete(), 0, 3);
		world.setBlock(x + 17, y + 5, z + 10, Blocks.stone_stairs, 2, 3);
		world.setBlock(x + 18, y + 5, z + 10, Blocks.stone_stairs, 2, 3);
		world.setBlock(x + 19, y + 5, z + 10, ModBlocks.fence_metal, 0, 3);
		world.setBlock(x + 23, y + 5, z + 10, Blocks.web, 0, 3);
		world.setBlock(x + 37, y + 5, z + 10, Library.getRandomConcrete(), 0, 3);
		world.setBlock(x + 4, y + 5, z + 11, this.Block5, 0, 3);
		world.setBlock(x + 12, y + 5, z + 11, this.Block5, 0, 3);
		world.setBlock(x + 16, y + 5, z + 11, Library.getRandomConcrete(), 0, 3);
		world.setBlock(x + 17, y + 5, z + 11, Blocks.stone_stairs, 7, 3);
		world.setBlock(x + 18, y + 5, z + 11, Blocks.stone_stairs, 7, 3);
		world.setBlock(x + 19, y + 5, z + 11, ModBlocks.fence_metal, 0, 3);
		world.setBlock(x + 20, y + 5, z + 11, Blocks.web, 0, 3);
		world.setBlock(x + 23, y + 5, z + 11, this.Block11, 0, 3);
		world.setBlock(x + 27, y + 5, z + 11, Blocks.vine, 8, 3);
		world.setBlock(x + 28, y + 5, z + 11, this.Block16, 4, 3);
		world.setBlock(x + 29, y + 5, z + 11, this.Block16, 2, 3);
		world.setBlock(x + 30, y + 5, z + 11, this.Block16, 3, 3);
		world.setBlock(x + 37, y + 5, z + 11, Library.getRandomConcrete(), 0, 3);
		world.setBlock(x + 4, y + 5, z + 12, this.Block5, 0, 3);
		world.setBlock(x + 8, y + 5, z + 12, this.Block25, 0, 3);
		world.setBlock(x + 12, y + 5, z + 12, this.Block5, 0, 3);
		world.setBlock(x + 16, y + 5, z + 12, Library.getRandomConcrete(), 0, 3);
		world.setBlock(x + 17, y + 5, z + 12, Blocks.web, 0, 3);
		world.setBlock(x + 19, y + 5, z + 12, ModBlocks.fence_metal, 0, 3);
		world.setBlock(x + 22, y + 5, z + 12, Blocks.vine, 8, 3);
		world.setBlock(x + 24, y + 5, z + 12, Blocks.vine, 2, 3);
		world.setBlock(x + 27, y + 5, z + 12, Blocks.vine, 8, 3);
		world.setBlock(x + 28, y + 5, z + 12, this.Block16, 4, 3);
		world.setBlock(x + 29, y + 5, z + 12, this.Block26, 0, 3);
		world.setBlock(x + 30, y + 5, z + 12, this.Block16, 3, 3);
		world.setBlock(x + 31, y + 5, z + 12, Blocks.vine, 2, 3);
		world.setBlock(x + 36, y + 5, z + 12, Blocks.vine, 8, 3);
		world.setBlock(x + 37, y + 5, z + 12, Library.getRandomConcrete(), 0, 3);
		world.setBlock(x + 4, y + 5, z + 13, this.Block5, 0, 3);
		world.setBlock(x + 12, y + 5, z + 13, this.Block5, 0, 3);
		world.setBlock(x + 16, y + 5, z + 13, Library.getRandomConcrete(), 0, 3);
		world.setBlock(x + 17, y + 5, z + 13, Blocks.vine, 2, 3);
		world.setBlock(x + 19, y + 5, z + 13, ModBlocks.fence_metal, 0, 3);
		world.setBlock(x + 23, y + 5, z + 13, this.Block11, 0, 3);
		world.setBlock(x + 28, y + 5, z + 13, this.Block16, 3, 3);
		world.setBlock(x + 29, y + 5, z + 13, this.Block16, 3, 3);
		world.setBlock(x + 30, y + 5, z + 13, this.Block16, 3, 3);
		world.setBlock(x + 31, y + 5, z + 13, Blocks.web, 0, 3);
		world.setBlock(x + 35, y + 5, z + 13, Blocks.vine, 4, 3);
		world.setBlock(x + 36, y + 5, z + 13, Blocks.vine, 8, 3);
		world.setBlock(x + 37, y + 5, z + 13, Library.getRandomConcrete(), 0, 3);
		world.setBlock(x + 4, y + 5, z + 14, this.Block5, 0, 3);
		world.setBlock(x + 12, y + 5, z + 14, this.Block5, 0, 3);
		world.setBlock(x + 16, y + 5, z + 14, Library.getRandomConcrete(), 0, 3);
		world.setBlock(x + 17, y + 5, z + 14, Blocks.vine, 2, 3);
		world.setBlock(x + 23, y + 5, z + 14, Library.getRandomConcrete(), 0, 3);
		world.setBlock(x + 24, y + 5, z + 14, Blocks.redstone_wire, 0, 3);
		world.setBlock(x + 27, y + 5, z + 14, Blocks.web, 0, 3);
		world.setBlock(x + 29, y + 5, z + 14, this.Block25, 0, 3);
		world.setBlock(x + 37, y + 5, z + 14, Blocks.gravel, 0, 3);
		world.setBlock(x + 5, y + 5, z + 15, this.Block5, 0, 3);
		world.setBlock(x + 11, y + 5, z + 15, this.Block5, 0, 3);
		world.setBlock(x + 16, y + 5, z + 15, this.Block11, 0, 3);
		world.setBlock(x + 17, y + 5, z + 15, Blocks.vine, 2, 3);
		//world.setBlock(x + 23, y + 5, z + 15, Blocks.iron_door, 8, 3);
		world.setBlock(x + 24, y + 5, z + 15, Blocks.vine, 2, 3);
		world.setBlock(x + 34, y + 5, z + 15, Blocks.vine, 2, 3);
		world.setBlock(x + 37, y + 5, z + 15, Blocks.gravel, 0, 3);
		world.setBlock(x + 6, y + 5, z + 16, this.Block5, 0, 3);
		world.setBlock(x + 7, y + 5, z + 16, this.Block5, 0, 3);
		world.setBlock(x + 8, y + 5, z + 16, this.Block5, 0, 3);
		world.setBlock(x + 9, y + 5, z + 16, this.Block5, 0, 3);
		world.setBlock(x + 10, y + 5, z + 16, this.Block5, 0, 3);
		world.setBlock(x + 16, y + 5, z + 16, this.Block11, 0, 3);
		world.setBlock(x + 22, y + 5, z + 16, Blocks.vine, 8, 3);
		//world.setBlock(x + 23, y + 5, z + 16, Blocks.iron_door, 8, 3);
		world.setBlock(x + 34, y + 5, z + 16, Blocks.vine, 2, 3);
		world.setBlock(x + 16, y + 5, z + 17, Library.getRandomConcrete(), 0, 3);
		world.setBlock(x + 21, y + 5, z + 17, Blocks.vine, 1, 3);
		world.setBlock(x + 22, y + 5, z + 17, Blocks.vine, 8, 3);
		world.setBlock(x + 23, y + 5, z + 17, Library.getRandomConcrete(), 0, 3);
		world.setBlock(x + 24, y + 5, z + 17, Blocks.web, 0, 3);
		world.setBlock(x + 27, y + 5, z + 17, Blocks.vine, 1, 3);
		world.setBlock(x + 28, y + 5, z + 17, Blocks.vine, 1, 3);
		world.setBlock(x + 33, y + 5, z + 17, Blocks.vine, 3, 3);
		world.setBlock(x + 16, y + 5, z + 18, Library.getRandomConcrete(), 0, 3);
		world.setBlock(x + 17, y + 5, z + 18, Library.getRandomConcrete(), 0, 3);
		world.setBlock(x + 18, y + 5, z + 18, Library.getRandomConcrete(), 0, 3);
		world.setBlock(x + 19, y + 5, z + 18, Library.getRandomConcrete(), 0, 3);
		world.setBlock(x + 20, y + 5, z + 18, Library.getRandomConcrete(), 0, 3);
		world.setBlock(x + 21, y + 5, z + 18, Library.getRandomConcrete(), 0, 3);
		world.setBlock(x + 22, y + 5, z + 18, Library.getRandomConcrete(), 0, 3);
		world.setBlock(x + 23, y + 5, z + 18, Library.getRandomConcrete(), 0, 3);
		world.setBlock(x + 24, y + 5, z + 18, Library.getRandomConcrete(), 0, 3);
		world.setBlock(x + 25, y + 5, z + 18, Library.getRandomConcrete(), 0, 3);
		world.setBlock(x + 26, y + 5, z + 18, Library.getRandomConcrete(), 0, 3);
		world.setBlock(x + 27, y + 5, z + 18, Library.getRandomConcrete(), 0, 3);
		world.setBlock(x + 28, y + 5, z + 18, Library.getRandomConcrete(), 0, 3);
		world.setBlock(x + 29, y + 5, z + 18, Library.getRandomConcrete(), 0, 3);
		world.setBlock(x + 30, y + 5, z + 18, Library.getRandomConcrete(), 0, 3);
		world.setBlock(x + 31, y + 5, z + 18, Library.getRandomConcrete(), 0, 3);
		world.setBlock(x + 32, y + 5, z + 18, Library.getRandomConcrete(), 0, 3);
		world.setBlock(x + 33, y + 5, z + 18, Library.getRandomConcrete(), 0, 3);
		world.setBlock(x + 34, y + 5, z + 18, Library.getRandomConcrete(), 0, 3);
		world.setBlock(x + 6, y + 5, z + 21, this.Block15, 0, 3);
		world.setBlock(x + 7, y + 5, z + 21, this.Block15, 0, 3);
		world.setBlock(x + 8, y + 5, z + 21, this.Block15, 0, 3);
		world.setBlock(x + 9, y + 5, z + 21, this.Block15, 0, 3);
		world.setBlock(x + 10, y + 5, z + 21, this.Block15, 0, 3);
		world.setBlock(x + 5, y + 5, z + 22, this.Block15, 0, 3);
		world.setBlock(x + 11, y + 5, z + 22, this.Block15, 0, 3);
		world.setBlock(x + 4, y + 5, z + 23, this.Block15, 0, 3);
		world.setBlock(x + 12, y + 5, z + 23, this.Block15, 0, 3);
		world.setBlock(x + 4, y + 5, z + 24, this.Block15, 0, 3);
		world.setBlock(x + 12, y + 5, z + 24, this.Block15, 0, 3);
		world.setBlock(x + 4, y + 5, z + 25, this.Block15, 0, 3);
		world.setBlock(x + 12, y + 5, z + 25, this.Block15, 0, 3);
		world.setBlock(x + 4, y + 5, z + 26, this.Block15, 0, 3);
		world.setBlock(x + 12, y + 5, z + 26, this.Block15, 0, 3);
		world.setBlock(x + 4, y + 5, z + 27, this.Block15, 0, 3);
		world.setBlock(x + 12, y + 5, z + 27, this.Block15, 0, 3);
		world.setBlock(x + 5, y + 5, z + 28, this.Block15, 0, 3);
		world.setBlock(x + 11, y + 5, z + 28, this.Block15, 0, 3);
		world.setBlock(x + 6, y + 5, z + 29, this.Block15, 0, 3);
		world.setBlock(x + 7, y + 5, z + 29, this.Block15, 0, 3);
		world.setBlock(x + 8, y + 5, z + 29, this.Block15, 0, 3);
		world.setBlock(x + 9, y + 5, z + 29, this.Block15, 0, 3);
		world.setBlock(x + 10, y + 5, z + 29, this.Block15, 0, 3);
		world.setBlock(x + 16, y + 6, z + 6, Library.getRandomConcrete(), 0, 3);
		world.setBlock(x + 17, y + 6, z + 6, Library.getRandomConcrete(), 0, 3);
		world.setBlock(x + 18, y + 6, z + 6, Library.getRandomConcrete(), 0, 3);
		world.setBlock(x + 19, y + 6, z + 6, Library.getRandomConcrete(), 0, 3);
		world.setBlock(x + 20, y + 6, z + 6, Library.getRandomConcrete(), 0, 3);
		world.setBlock(x + 21, y + 6, z + 6, Library.getRandomConcrete(), 0, 3);
		world.setBlock(x + 22, y + 6, z + 6, Library.getRandomConcrete(), 0, 3);
		world.setBlock(x + 23, y + 6, z + 6, Library.getRandomConcrete(), 0, 3);
		world.setBlock(x + 24, y + 6, z + 6, Library.getRandomConcrete(), 0, 3);
		world.setBlock(x + 25, y + 6, z + 6, Library.getRandomConcrete(), 0, 3);
		world.setBlock(x + 26, y + 6, z + 6, Library.getRandomConcrete(), 0, 3);
		world.setBlock(x + 27, y + 6, z + 6, Library.getRandomConcrete(), 0, 3);
		world.setBlock(x + 28, y + 6, z + 6, Library.getRandomConcrete(), 0, 3);
		world.setBlock(x + 29, y + 6, z + 6, Library.getRandomConcrete(), 0, 3);
		world.setBlock(x + 30, y + 6, z + 6, Library.getRandomConcrete(), 0, 3);
		world.setBlock(x + 31, y + 6, z + 6, Library.getRandomConcrete(), 0, 3);
		world.setBlock(x + 32, y + 6, z + 6, Library.getRandomConcrete(), 0, 3);
		world.setBlock(x + 33, y + 6, z + 6, Library.getRandomConcrete(), 0, 3);
		world.setBlock(x + 34, y + 6, z + 6, Library.getRandomConcrete(), 0, 3);
		world.setBlock(x + 35, y + 6, z + 6, Library.getRandomConcrete(), 0, 3);
		world.setBlock(x + 36, y + 6, z + 6, Library.getRandomConcrete(), 0, 3);
		world.setBlock(x + 37, y + 6, z + 6, Library.getRandomConcrete(), 0, 3);
		world.setBlock(x + 7, y + 6, z + 7, this.Block5, 0, 3);
		world.setBlock(x + 8, y + 6, z + 7, this.Block5, 0, 3);
		world.setBlock(x + 9, y + 6, z + 7, this.Block5, 0, 3);
		world.setBlock(x + 16, y + 6, z + 7, Library.getRandomConcrete(), 0, 3);
		world.setBlock(x + 18, y + 6, z + 7, Blocks.vine, 4, 3);
		world.setBlock(x + 19, y + 6, z + 7, Blocks.vine, 4, 3);
		world.setBlock(x + 20, y + 6, z + 7, Blocks.vine, 4, 3);
		world.setBlock(x + 21, y + 6, z + 7, Blocks.web, 0, 3);
		world.setBlock(x + 22, y + 6, z + 7, Blocks.web, 0, 3);
		world.setBlock(x + 23, y + 6, z + 7, Library.getRandomConcrete(), 0, 3);
		world.setBlock(x + 24, y + 6, z + 7, Blocks.web, 0, 3);
		world.setBlock(x + 25, y + 6, z + 7, this.Block8, 3, 3);
		world.setBlock(x + 26, y + 6, z + 7, Blocks.web, 0, 3);
		world.setBlock(x + 27, y + 6, z + 7, Blocks.web, 0, 3);
		world.setBlock(x + 29, y + 6, z + 7, Blocks.web, 0, 3);
		world.setBlock(x + 30, y + 6, z + 7, Blocks.vine, 4, 3);
		world.setBlock(x + 31, y + 6, z + 7, Blocks.web, 0, 3);
		world.setBlock(x + 33, y + 6, z + 7, this.Block22, 0, 3);
		world.setBlock(x + 34, y + 6, z + 7, this.Block22, 0, 3);
		world.setBlock(x + 35, y + 6, z + 7, this.Block22, 0, 3);
		world.setBlock(x + 36, y + 6, z + 7, this.Block22, 0, 3);
		world.setBlock(x + 37, y + 6, z + 7, Library.getRandomConcrete(), 0, 3);
		world.setBlock(x + 6, y + 6, z + 8, this.Block5, 0, 3);
		world.setBlock(x + 7, y + 6, z + 8, this.Block5, 0, 3);
		world.setBlock(x + 8, y + 6, z + 8, this.Block5, 0, 3);
		world.setBlock(x + 9, y + 6, z + 8, this.Block5, 0, 3);
		world.setBlock(x + 10, y + 6, z + 8, this.Block5, 0, 3);
		world.setBlock(x + 16, y + 6, z + 8, Library.getRandomConcrete(), 0, 3);
		world.setBlock(x + 22, y + 6, z + 8, Blocks.web, 0, 3);
		world.setBlock(x + 23, y + 6, z + 8, Library.getRandomConcrete(), 0, 3);
		world.setBlock(x + 26, y + 6, z + 8, Blocks.web, 0, 3);
		world.setBlock(x + 32, y + 6, z + 8, Blocks.web, 0, 3);
		world.setBlock(x + 33, y + 6, z + 8, this.Block22, 0, 3);
		world.setBlock(x + 34, y + 6, z + 8, this.Block22, 0, 3);
		world.setBlock(x + 35, y + 6, z + 8, this.Block22, 0, 3);
		world.setBlock(x + 36, y + 6, z + 8, this.Block22, 0, 3);
		world.setBlock(x + 37, y + 6, z + 8, Library.getRandomConcrete(), 0, 3);
		world.setBlock(x + 5, y + 6, z + 9, this.Block5, 0, 3);
		world.setBlock(x + 6, y + 6, z + 9, this.Block5, 0, 3);
		world.setBlock(x + 7, y + 6, z + 9, this.Block5, 0, 3);
		world.setBlock(x + 8, y + 6, z + 9, this.Block5, 0, 3);
		world.setBlock(x + 9, y + 6, z + 9, this.Block5, 0, 3);
		world.setBlock(x + 10, y + 6, z + 9, this.Block5, 0, 3);
		world.setBlock(x + 11, y + 6, z + 9, this.Block5, 0, 3);
		world.setBlock(x + 16, y + 6, z + 9, Library.getRandomConcrete(), 0, 3);
		world.setBlock(x + 23, y + 6, z + 9, Library.getRandomConcrete(), 0, 3);
		world.setBlock(x + 25, y + 6, z + 9, Blocks.web, 0, 3);
		world.setBlock(x + 30, y + 6, z + 9, Blocks.web, 0, 3);
		world.setBlock(x + 33, y + 6, z + 9, Blocks.vine, 4, 3);
		world.setBlock(x + 35, y + 6, z + 9, Blocks.web, 0, 3);
		world.setBlock(x + 36, y + 6, z + 9, Blocks.web, 0, 3);
		world.setBlock(x + 37, y + 6, z + 9, Library.getRandomConcrete(), 0, 3);
		world.setBlock(x + 4, y + 6, z + 10, this.Block5, 0, 3);
		world.setBlock(x + 5, y + 6, z + 10, this.Block5, 0, 3);
		world.setBlock(x + 6, y + 6, z + 10, this.Block5, 0, 3);
		world.setBlock(x + 10, y + 6, z + 10, this.Block5, 0, 3);
		world.setBlock(x + 11, y + 6, z + 10, this.Block5, 0, 3);
		world.setBlock(x + 12, y + 6, z + 10, this.Block5, 0, 3);
		world.setBlock(x + 16, y + 6, z + 10, Library.getRandomConcrete(), 0, 3);
		world.setBlock(x + 19, y + 6, z + 10, ModBlocks.fence_metal, 0, 3);
		world.setBlock(x + 23, y + 6, z + 10, Library.getRandomConcrete(), 0, 3);
		world.setBlock(x + 24, y + 6, z + 10, Blocks.web, 0, 3);
		world.setBlock(x + 30, y + 6, z + 10, Blocks.web, 0, 3);
		world.setBlock(x + 36, y + 6, z + 10, Blocks.web, 0, 3);
		world.setBlock(x + 37, y + 6, z + 10, Library.getRandomConcrete(), 0, 3);
		world.setBlock(x + 4, y + 6, z + 11, this.Block5, 0, 3);
		world.setBlock(x + 5, y + 6, z + 11, this.Block5, 0, 3);
		world.setBlock(x + 11, y + 6, z + 11, this.Block5, 0, 3);
		world.setBlock(x + 12, y + 6, z + 11, this.Block5, 0, 3);
		world.setBlock(x + 16, y + 6, z + 11, Library.getRandomConcrete(), 0, 3);
		world.setBlock(x + 17, y + 6, z + 11, Blocks.stone_stairs, 2, 3);
		world.setBlock(x + 18, y + 6, z + 11, Blocks.stone_stairs, 2, 3);
		world.setBlock(x + 19, y + 6, z + 11, ModBlocks.fence_metal, 0, 3);
		world.setBlock(x + 20, y + 6, z + 11, Blocks.web, 0, 3);
		world.setBlock(x + 23, y + 6, z + 11, Library.getRandomConcrete(), 0, 3);
		world.setBlock(x + 27, y + 6, z + 11, Blocks.vine, 8, 3);
		world.setBlock(x + 28, y + 6, z + 11, this.Block24, 0, 3);
		world.setBlock(x + 29, y + 6, z + 11, this.Block24, 0, 3);
		world.setBlock(x + 30, y + 6, z + 11, this.Block24, 0, 3);
		world.setBlock(x + 31, y + 6, z + 11, Blocks.web, 0, 3);
		world.setBlock(x + 37, y + 6, z + 11, Library.getRandomConcrete(), 0, 3);
		world.setBlock(x + 4, y + 6, z + 12, this.Block5, 0, 3);
		world.setBlock(x + 5, y + 6, z + 12, this.Block5, 0, 3);
		world.setBlock(x + 8, y + 6, z + 12, this.Block25, 0, 3);
		world.setBlock(x + 11, y + 6, z + 12, this.Block5, 0, 3);
		world.setBlock(x + 12, y + 6, z + 12, this.Block5, 0, 3);
		world.setBlock(x + 16, y + 6, z + 12, Library.getRandomConcrete(), 0, 3);
		world.setBlock(x + 17, y + 6, z + 12, Blocks.stone_stairs, 7, 3);
		world.setBlock(x + 18, y + 6, z + 12, Blocks.stone_stairs, 7, 3);
		world.setBlock(x + 19, y + 6, z + 12, ModBlocks.fence_metal, 0, 3);
		world.setBlock(x + 20, y + 6, z + 12, Blocks.web, 0, 3);
		world.setBlock(x + 22, y + 6, z + 12, Blocks.vine, 8, 3);
		world.setBlock(x + 23, y + 6, z + 12, Library.getRandomConcrete(), 0, 3);
		world.setBlock(x + 24, y + 6, z + 12, Blocks.vine, 2, 3);
		world.setBlock(x + 27, y + 6, z + 12, Blocks.vine, 8, 3);
		world.setBlock(x + 28, y + 6, z + 12, this.Block24, 0, 3);
		world.setBlock(x + 29, y + 6, z + 12, this.Block24, 0, 3);
		world.setBlock(x + 30, y + 6, z + 12, this.Block24, 0, 3);
		world.setBlock(x + 31, y + 6, z + 12, Blocks.vine, 2, 3);
		world.setBlock(x + 36, y + 6, z + 12, Blocks.vine, 8, 3);
		world.setBlock(x + 37, y + 6, z + 12, Library.getRandomConcrete(), 0, 3);
		world.setBlock(x + 4, y + 6, z + 13, this.Block5, 0, 3);
		world.setBlock(x + 5, y + 6, z + 13, this.Block5, 0, 3);
		world.setBlock(x + 11, y + 6, z + 13, this.Block5, 0, 3);
		world.setBlock(x + 12, y + 6, z + 13, this.Block5, 0, 3);
		world.setBlock(x + 16, y + 6, z + 13, Library.getRandomConcrete(), 0, 3);
		world.setBlock(x + 17, y + 6, z + 13, Blocks.web, 0, 3);
		world.setBlock(x + 23, y + 6, z + 13, Library.getRandomConcrete(), 0, 3);
		world.setBlock(x + 27, y + 6, z + 13, Blocks.web, 0, 3);
		world.setBlock(x + 28, y + 6, z + 13, this.Block24, 0, 3);
		world.setBlock(x + 29, y + 6, z + 13, this.Block24, 0, 3);
		world.setBlock(x + 30, y + 6, z + 13, this.Block24, 0, 3);
		world.setBlock(x + 31, y + 6, z + 13, Blocks.vine, 2, 3);
		world.setBlock(x + 35, y + 6, z + 13, Blocks.vine, 4, 3);
		world.setBlock(x + 36, y + 6, z + 13, Blocks.vine, 8, 3);
		world.setBlock(x + 37, y + 6, z + 13, Blocks.gravel, 0, 3);
		world.setBlock(x + 4, y + 6, z + 14, this.Block5, 0, 3);
		world.setBlock(x + 5, y + 6, z + 14, this.Block5, 0, 3);
		world.setBlock(x + 6, y + 6, z + 14, this.Block5, 0, 3);
		world.setBlock(x + 10, y + 6, z + 14, this.Block5, 0, 3);
		world.setBlock(x + 11, y + 6, z + 14, this.Block5, 0, 3);
		world.setBlock(x + 12, y + 6, z + 14, this.Block5, 0, 3);
		world.setBlock(x + 16, y + 6, z + 14, Library.getRandomConcrete(), 0, 3);
		world.setBlock(x + 17, y + 6, z + 14, Blocks.vine, 2, 3);
		world.setBlock(x + 23, y + 6, z + 14, Library.getRandomConcrete(), 0, 3);
		world.setBlock(x + 24, y + 6, z + 14, Blocks.vine, 2, 3);
		world.setBlock(x + 26, y + 6, z + 14, Blocks.web, 0, 3);
		world.setBlock(x + 28, y + 6, z + 14, Blocks.web, 0, 3);
		world.setBlock(x + 29, y + 6, z + 14, this.Block25, 0, 3);
		world.setBlock(x + 5, y + 6, z + 15, this.Block5, 0, 3);
		world.setBlock(x + 6, y + 6, z + 15, this.Block5, 0, 3);
		world.setBlock(x + 7, y + 6, z + 15, this.Block5, 0, 3);
		world.setBlock(x + 8, y + 6, z + 15, this.Block5, 0, 3);
		world.setBlock(x + 9, y + 6, z + 15, this.Block5, 0, 3);
		world.setBlock(x + 10, y + 6, z + 15, this.Block5, 0, 3);
		world.setBlock(x + 11, y + 6, z + 15, this.Block5, 0, 3);
		world.setBlock(x + 16, y + 6, z + 15, Library.getRandomConcrete(), 0, 3);
		world.setBlock(x + 17, y + 6, z + 15, Blocks.vine, 2, 3);
		world.setBlock(x + 23, y + 6, z + 15, Library.getRandomConcrete(), 0, 3);
		world.setBlock(x + 24, y + 6, z + 15, Blocks.vine, 2, 3);
		world.setBlock(x + 27, y + 6, z + 15, Blocks.web, 0, 3);
		world.setBlock(x + 34, y + 6, z + 15, Blocks.vine, 2, 3);
		world.setBlock(x + 6, y + 6, z + 16, this.Block5, 0, 3);
		world.setBlock(x + 7, y + 6, z + 16, this.Block5, 0, 3);
		world.setBlock(x + 8, y + 6, z + 16, this.Block5, 0, 3);
		world.setBlock(x + 9, y + 6, z + 16, this.Block5, 0, 3);
		world.setBlock(x + 10, y + 6, z + 16, this.Block5, 0, 3);
		world.setBlock(x + 16, y + 6, z + 16, Library.getRandomConcrete(), 0, 3);
		world.setBlock(x + 17, y + 6, z + 16, Blocks.web, 0, 3);
		world.setBlock(x + 22, y + 6, z + 16, Blocks.vine, 8, 3);
		world.setBlock(x + 23, y + 6, z + 16, Library.getRandomConcrete(), 0, 3);
		world.setBlock(x + 24, y + 6, z + 16, Blocks.web, 0, 3);
		world.setBlock(x + 29, y + 6, z + 16, Blocks.web, 0, 3);
		world.setBlock(x + 34, y + 6, z + 16, Blocks.vine, 2, 3);
		world.setBlock(x + 16, y + 6, z + 17, Library.getRandomConcrete(), 0, 3);
		world.setBlock(x + 17, y + 6, z + 17, Blocks.web, 0, 3);
		world.setBlock(x + 18, y + 6, z + 17, Blocks.web, 0, 3);
		world.setBlock(x + 20, y + 6, z + 17, Blocks.web, 0, 3);
		world.setBlock(x + 21, y + 6, z + 17, Blocks.vine, 1, 3);
		world.setBlock(x + 22, y + 6, z + 17, Blocks.vine, 8, 3);
		world.setBlock(x + 23, y + 6, z + 17, Library.getRandomConcrete(), 0, 3);
		world.setBlock(x + 25, y + 6, z + 17, Blocks.web, 0, 3);
		world.setBlock(x + 27, y + 6, z + 17, Blocks.vine, 1, 3);
		world.setBlock(x + 28, y + 6, z + 17, Blocks.web, 0, 3);
		world.setBlock(x + 30, y + 6, z + 17, Blocks.web, 0, 3);
		world.setBlock(x + 33, y + 6, z + 17, Blocks.vine, 3, 3);
		world.setBlock(x + 16, y + 6, z + 18, Library.getRandomConcrete(), 0, 3);
		world.setBlock(x + 17, y + 6, z + 18, Library.getRandomConcrete(), 0, 3);
		world.setBlock(x + 18, y + 6, z + 18, Library.getRandomConcrete(), 0, 3);
		world.setBlock(x + 19, y + 6, z + 18, Library.getRandomConcrete(), 0, 3);
		world.setBlock(x + 20, y + 6, z + 18, Library.getRandomConcrete(), 0, 3);
		world.setBlock(x + 21, y + 6, z + 18, Library.getRandomConcrete(), 0, 3);
		world.setBlock(x + 22, y + 6, z + 18, Library.getRandomConcrete(), 0, 3);
		world.setBlock(x + 23, y + 6, z + 18, Library.getRandomConcrete(), 0, 3);
		world.setBlock(x + 24, y + 6, z + 18, Library.getRandomConcrete(), 0, 3);
		world.setBlock(x + 25, y + 6, z + 18, Library.getRandomConcrete(), 0, 3);
		world.setBlock(x + 26, y + 6, z + 18, Library.getRandomConcrete(), 0, 3);
		world.setBlock(x + 27, y + 6, z + 18, Library.getRandomConcrete(), 0, 3);
		world.setBlock(x + 28, y + 6, z + 18, Library.getRandomConcrete(), 0, 3);
		world.setBlock(x + 29, y + 6, z + 18, Library.getRandomConcrete(), 0, 3);
		world.setBlock(x + 30, y + 6, z + 18, Library.getRandomConcrete(), 0, 3);
		world.setBlock(x + 31, y + 6, z + 18, Library.getRandomConcrete(), 0, 3);
		world.setBlock(x + 32, y + 6, z + 18, Library.getRandomConcrete(), 0, 3);
		world.setBlock(x + 33, y + 6, z + 18, Library.getRandomConcrete(), 0, 3);
		world.setBlock(x + 34, y + 6, z + 18, Blocks.gravel, 0, 3);
		world.setBlock(x + 6, y + 6, z + 21, this.Block15, 0, 3);
		world.setBlock(x + 7, y + 6, z + 21, this.Block15, 0, 3);
		world.setBlock(x + 8, y + 6, z + 21, this.Block15, 0, 3);
		world.setBlock(x + 9, y + 6, z + 21, this.Block15, 0, 3);
		world.setBlock(x + 10, y + 6, z + 21, this.Block15, 0, 3);
		world.setBlock(x + 5, y + 6, z + 22, this.Block15, 0, 3);
		world.setBlock(x + 11, y + 6, z + 22, this.Block15, 0, 3);
		world.setBlock(x + 4, y + 6, z + 23, this.Block15, 0, 3);
		world.setBlock(x + 12, y + 6, z + 23, this.Block15, 0, 3);
		world.setBlock(x + 4, y + 6, z + 24, this.Block15, 0, 3);
		world.setBlock(x + 12, y + 6, z + 24, this.Block15, 0, 3);
		world.setBlock(x + 4, y + 6, z + 25, this.Block15, 0, 3);
		world.setBlock(x + 12, y + 6, z + 25, this.Block15, 0, 3);
		world.setBlock(x + 4, y + 6, z + 26, this.Block15, 0, 3);
		world.setBlock(x + 12, y + 6, z + 26, this.Block15, 0, 3);
		world.setBlock(x + 4, y + 6, z + 27, this.Block15, 0, 3);
		world.setBlock(x + 12, y + 6, z + 27, this.Block15, 0, 3);
		world.setBlock(x + 5, y + 6, z + 28, this.Block15, 0, 3);
		world.setBlock(x + 11, y + 6, z + 28, this.Block15, 0, 3);
		world.setBlock(x + 6, y + 6, z + 29, this.Block15, 0, 3);
		world.setBlock(x + 7, y + 6, z + 29, this.Block15, 0, 3);
		world.setBlock(x + 8, y + 6, z + 29, this.Block15, 0, 3);
		world.setBlock(x + 9, y + 6, z + 29, this.Block15, 0, 3);
		world.setBlock(x + 10, y + 6, z + 29, this.Block15, 0, 3);
		world.setBlock(x + 16, y + 7, z + 6, Library.getRandomConcrete(), 0, 3);
		world.setBlock(x + 17, y + 7, z + 6, Library.getRandomConcrete(), 0, 3);
		world.setBlock(x + 18, y + 7, z + 6, Library.getRandomConcrete(), 0, 3);
		world.setBlock(x + 19, y + 7, z + 6, Library.getRandomConcrete(), 0, 3);
		world.setBlock(x + 20, y + 7, z + 6, Library.getRandomConcrete(), 0, 3);
		world.setBlock(x + 21, y + 7, z + 6, Library.getRandomConcrete(), 0, 3);
		world.setBlock(x + 22, y + 7, z + 6, Library.getRandomConcrete(), 0, 3);
		world.setBlock(x + 23, y + 7, z + 6, Library.getRandomConcrete(), 0, 3);
		world.setBlock(x + 24, y + 7, z + 6, Library.getRandomConcrete(), 0, 3);
		world.setBlock(x + 25, y + 7, z + 6, Library.getRandomConcrete(), 0, 3);
		world.setBlock(x + 26, y + 7, z + 6, Library.getRandomConcrete(), 0, 3);
		world.setBlock(x + 27, y + 7, z + 6, Library.getRandomConcrete(), 0, 3);
		world.setBlock(x + 28, y + 7, z + 6, Library.getRandomConcrete(), 0, 3);
		world.setBlock(x + 29, y + 7, z + 6, Library.getRandomConcrete(), 0, 3);
		world.setBlock(x + 30, y + 7, z + 6, Library.getRandomConcrete(), 0, 3);
		world.setBlock(x + 31, y + 7, z + 6, Library.getRandomConcrete(), 0, 3);
		world.setBlock(x + 32, y + 7, z + 6, Library.getRandomConcrete(), 0, 3);
		world.setBlock(x + 33, y + 7, z + 6, Library.getRandomConcrete(), 0, 3);
		world.setBlock(x + 34, y + 7, z + 6, Library.getRandomConcrete(), 0, 3);
		world.setBlock(x + 35, y + 7, z + 6, Library.getRandomConcrete(), 0, 3);
		world.setBlock(x + 36, y + 7, z + 6, Library.getRandomConcrete(), 0, 3);
		world.setBlock(x + 16, y + 7, z + 7, Library.getRandomConcrete(), 0, 3);
		world.setBlock(x + 19, y + 7, z + 7, this.Block6, 0, 3);
		world.setBlock(x + 20, y + 7, z + 7, this.Block6, 0, 3);
		world.setBlock(x + 21, y + 7, z + 7, this.Block6, 0, 3);
		world.setBlock(x + 22, y + 7, z + 7, this.Block6, 0, 3);
		world.setBlock(x + 23, y + 7, z + 7, this.Block6, 0, 3);
		world.setBlock(x + 24, y + 7, z + 7, this.Block6, 0, 3);
		world.setBlock(x + 25, y + 7, z + 7, this.Block6, 0, 3);
		world.setBlock(x + 26, y + 7, z + 7, this.Block6, 0, 3);
		world.setBlock(x + 27, y + 7, z + 7, this.Block6, 0, 3);
		world.setBlock(x + 28, y + 7, z + 7, this.Block6, 0, 3);
		world.setBlock(x + 29, y + 7, z + 7, this.Block6, 0, 3);
		world.setBlock(x + 30, y + 7, z + 7, this.Block6, 0, 3);
		world.setBlock(x + 31, y + 7, z + 7, this.Block6, 0, 3);
		world.setBlock(x + 32, y + 7, z + 7, this.Block6, 0, 3);
		world.setBlock(x + 33, y + 7, z + 7, this.Block6, 0, 3);
		world.setBlock(x + 34, y + 7, z + 7, this.Block6, 0, 3);
		world.setBlock(x + 35, y + 7, z + 7, this.Block6, 0, 3);
		world.setBlock(x + 36, y + 7, z + 7, this.Block6, 0, 3);
		world.setBlock(x + 37, y + 7, z + 7, Library.getRandomConcrete(), 0, 3);
		world.setBlock(x + 16, y + 7, z + 8, Library.getRandomConcrete(), 0, 3);
		world.setBlock(x + 19, y + 7, z + 8, this.Block6, 0, 3);
		world.setBlock(x + 20, y + 7, z + 8, this.Block6, 0, 3);
		world.setBlock(x + 21, y + 7, z + 8, this.Block6, 0, 3);
		world.setBlock(x + 22, y + 7, z + 8, this.Block6, 0, 3);
		world.setBlock(x + 23, y + 7, z + 8, this.Block6, 0, 3);
		world.setBlock(x + 24, y + 7, z + 8, this.Block6, 0, 3);
		world.setBlock(x + 25, y + 7, z + 8, this.Block6, 0, 3);
		world.setBlock(x + 26, y + 7, z + 8, this.Block6, 0, 3);
		world.setBlock(x + 27, y + 7, z + 8, this.Block6, 0, 3);
		world.setBlock(x + 28, y + 7, z + 8, this.Block6, 0, 3);
		world.setBlock(x + 29, y + 7, z + 8, this.Block6, 0, 3);
		world.setBlock(x + 30, y + 7, z + 8, this.Block6, 0, 3);
		world.setBlock(x + 31, y + 7, z + 8, this.Block6, 0, 3);
		world.setBlock(x + 32, y + 7, z + 8, this.Block6, 0, 3);
		world.setBlock(x + 33, y + 7, z + 8, this.Block6, 0, 3);
		world.setBlock(x + 34, y + 7, z + 8, this.Block6, 0, 3);
		world.setBlock(x + 35, y + 7, z + 8, this.Block6, 0, 3);
		world.setBlock(x + 36, y + 7, z + 8, this.Block6, 0, 3);
		world.setBlock(x + 37, y + 7, z + 8, Library.getRandomConcrete(), 0, 3);
		world.setBlock(x + 6, y + 7, z + 9, this.Block5, 0, 3);
		world.setBlock(x + 7, y + 7, z + 9, this.Block5, 0, 3);
		world.setBlock(x + 8, y + 7, z + 9, this.Block5, 0, 3);
		world.setBlock(x + 9, y + 7, z + 9, this.Block5, 0, 3);
		world.setBlock(x + 10, y + 7, z + 9, this.Block5, 0, 3);
		world.setBlock(x + 16, y + 7, z + 9, Library.getRandomConcrete(), 0, 3);
		world.setBlock(x + 19, y + 7, z + 9, this.Block6, 0, 3);
		world.setBlock(x + 20, y + 7, z + 9, this.Block25, 0, 3);
		world.setBlock(x + 21, y + 7, z + 9, this.Block25, 0, 3);
		world.setBlock(x + 22, y + 7, z + 9, this.Block25, 0, 3);
		world.setBlock(x + 23, y + 7, z + 9, this.Block25, 0, 3);
		world.setBlock(x + 24, y + 7, z + 9, this.Block6, 0, 3);
		world.setBlock(x + 25, y + 7, z + 9, this.Block6, 0, 3);
		world.setBlock(x + 26, y + 7, z + 9, this.Block6, 0, 3);
		world.setBlock(x + 27, y + 7, z + 9, this.Block6, 0, 3);
		world.setBlock(x + 28, y + 7, z + 9, this.Block6, 0, 3);
		world.setBlock(x + 29, y + 7, z + 9, this.Block6, 0, 3);
		world.setBlock(x + 30, y + 7, z + 9, this.Block6, 0, 3);
		world.setBlock(x + 31, y + 7, z + 9, this.Block6, 0, 3);
		world.setBlock(x + 32, y + 7, z + 9, this.Block6, 0, 3);
		world.setBlock(x + 33, y + 7, z + 9, this.Block6, 0, 3);
		world.setBlock(x + 34, y + 7, z + 9, this.Block6, 0, 3);
		world.setBlock(x + 35, y + 7, z + 9, this.Block6, 0, 3);
		world.setBlock(x + 36, y + 7, z + 9, this.Block6, 0, 3);
		world.setBlock(x + 37, y + 7, z + 9, Library.getRandomConcrete(), 0, 3);
		world.setBlock(x + 5, y + 7, z + 10, this.Block5, 0, 3);
		world.setBlock(x + 6, y + 7, z + 10, this.Block5, 0, 3);
		world.setBlock(x + 10, y + 7, z + 10, this.Block5, 0, 3);
		world.setBlock(x + 11, y + 7, z + 10, this.Block5, 0, 3);
		world.setBlock(x + 16, y + 7, z + 10, Library.getRandomConcrete(), 0, 3);
		world.setBlock(x + 19, y + 7, z + 10, this.Block6, 0, 3);
		world.setBlock(x + 20, y + 7, z + 10, this.Block25, 0, 3);
		world.setBlock(x + 21, y + 7, z + 10, this.Block6, 0, 3);
		world.setBlock(x + 22, y + 7, z + 10, this.Block6, 0, 3);
		world.setBlock(x + 23, y + 7, z + 10, this.Block6, 0, 3);
		world.setBlock(x + 24, y + 7, z + 10, this.Block6, 0, 3);
		world.setBlock(x + 25, y + 7, z + 10, this.Block6, 0, 3);
		world.setBlock(x + 26, y + 7, z + 10, this.Block6, 0, 3);
		world.setBlock(x + 27, y + 7, z + 10, this.Block6, 0, 3);
		world.setBlock(x + 28, y + 7, z + 10, this.Block6, 0, 3);
		world.setBlock(x + 29, y + 7, z + 10, this.Block6, 0, 3);
		world.setBlock(x + 30, y + 7, z + 10, this.Block6, 0, 3);
		world.setBlock(x + 31, y + 7, z + 10, this.Block6, 0, 3);
		world.setBlock(x + 32, y + 7, z + 10, this.Block6, 0, 3);
		world.setBlock(x + 33, y + 7, z + 10, this.Block6, 0, 3);
		world.setBlock(x + 34, y + 7, z + 10, this.Block6, 0, 3);
		world.setBlock(x + 35, y + 7, z + 10, this.Block6, 0, 3);
		world.setBlock(x + 36, y + 7, z + 10, this.Block18, 0, 3);
		world.setBlock(x + 37, y + 7, z + 10, Library.getRandomConcrete(), 0, 3);
		world.setBlock(x + 5, y + 7, z + 11, this.Block5, 0, 3);
		world.setBlock(x + 11, y + 7, z + 11, this.Block5, 0, 3);
		world.setBlock(x + 16, y + 7, z + 11, Library.getRandomConcrete(), 0, 3);
		world.setBlock(x + 19, y + 7, z + 11, this.Block6, 0, 3);
		world.setBlock(x + 20, y + 7, z + 11, this.Block25, 0, 3);
		world.setBlock(x + 21, y + 7, z + 11, this.Block6, 0, 3);
		world.setBlock(x + 22, y + 7, z + 11, this.Block6, 0, 3);
		world.setBlock(x + 23, y + 7, z + 11, this.Block6, 0, 3);
		world.setBlock(x + 24, y + 7, z + 11, this.Block6, 0, 3);
		world.setBlock(x + 25, y + 7, z + 11, this.Block6, 0, 3);
		world.setBlock(x + 26, y + 7, z + 11, this.Block6, 0, 3);
		world.setBlock(x + 27, y + 7, z + 11, this.Block6, 0, 3);
		world.setBlock(x + 28, y + 7, z + 11, this.Block6, 0, 3);
		world.setBlock(x + 29, y + 7, z + 11, this.Block6, 0, 3);
		world.setBlock(x + 30, y + 7, z + 11, this.Block6, 0, 3);
		world.setBlock(x + 31, y + 7, z + 11, this.Block6, 0, 3);
		world.setBlock(x + 32, y + 7, z + 11, this.Block6, 0, 3);
		world.setBlock(x + 33, y + 7, z + 11, this.Block6, 0, 3);
		world.setBlock(x + 34, y + 7, z + 11, this.Block6, 0, 3);
		world.setBlock(x + 35, y + 7, z + 11, this.Block18, 0, 3);
		world.setBlock(x + 36, y + 7, z + 11, this.Block18, 0, 3);
		world.setBlock(x + 37, y + 7, z + 11, Library.getRandomConcrete(), 0, 3);
		world.setBlock(x + 5, y + 7, z + 12, this.Block5, 0, 3);
		world.setBlock(x + 8, y + 7, z + 12, this.Block25, 0, 3);
		world.setBlock(x + 9, y + 7, z + 12, this.Block25, 0, 3);
		world.setBlock(x + 10, y + 7, z + 12, this.Block25, 0, 3);
		world.setBlock(x + 11, y + 7, z + 12, this.Block25, 0, 3);
		world.setBlock(x + 12, y + 7, z + 12, this.Block25, 0, 3);
		world.setBlock(x + 13, y + 7, z + 12, this.Block25, 0, 3);
		world.setBlock(x + 14, y + 7, z + 12, this.Block25, 0, 3);
		world.setBlock(x + 15, y + 7, z + 12, this.Block25, 0, 3);
		world.setBlock(x + 16, y + 7, z + 12, this.Block25, 0, 3);
		world.setBlock(x + 17, y + 7, z + 12, Blocks.stone_stairs, 2, 3);
		world.setBlock(x + 18, y + 7, z + 12, Blocks.stone_stairs, 2, 3);
		world.setBlock(x + 19, y + 7, z + 12, this.Block6, 0, 3);
		world.setBlock(x + 20, y + 7, z + 12, this.Block25, 0, 3);
		world.setBlock(x + 21, y + 7, z + 12, this.Block6, 0, 3);
		world.setBlock(x + 22, y + 7, z + 12, this.Block6, 0, 3);
		world.setBlock(x + 23, y + 7, z + 12, this.Block6, 0, 3);
		world.setBlock(x + 24, y + 7, z + 12, this.Block6, 0, 3);
		world.setBlock(x + 25, y + 7, z + 12, this.Block6, 0, 3);
		world.setBlock(x + 26, y + 7, z + 12, this.Block6, 0, 3);
		world.setBlock(x + 27, y + 7, z + 12, this.Block6, 0, 3);
		world.setBlock(x + 28, y + 7, z + 12, this.Block6, 0, 3);
		world.setBlock(x + 29, y + 7, z + 12, this.Block6, 0, 3);
		world.setBlock(x + 30, y + 7, z + 12, this.Block6, 0, 3);
		world.setBlock(x + 31, y + 7, z + 12, this.Block6, 0, 3);
		world.setBlock(x + 32, y + 7, z + 12, this.Block6, 0, 3);
		world.setBlock(x + 33, y + 7, z + 12, this.Block18, 0, 3);
		world.setBlock(x + 34, y + 7, z + 12, this.Block18, 0, 3);
		world.setBlock(x + 35, y + 7, z + 12, this.Block18, 0, 3);
		world.setBlock(x + 37, y + 7, z + 12, Blocks.gravel, 0, 3);
		world.setBlock(x + 5, y + 7, z + 13, this.Block5, 0, 3);
		world.setBlock(x + 11, y + 7, z + 13, this.Block5, 0, 3);
		world.setBlock(x + 16, y + 7, z + 13, this.Block25, 0, 3);
		world.setBlock(x + 17, y + 7, z + 13, this.Block6, 0, 3);
		world.setBlock(x + 18, y + 7, z + 13, this.Block6, 0, 3);
		world.setBlock(x + 19, y + 7, z + 13, this.Block6, 0, 3);
		world.setBlock(x + 20, y + 7, z + 13, this.Block25, 0, 3);
		world.setBlock(x + 21, y + 7, z + 13, this.Block6, 0, 3);
		world.setBlock(x + 22, y + 7, z + 13, this.Block6, 0, 3);
		world.setBlock(x + 23, y + 7, z + 13, this.Block6, 0, 3);
		world.setBlock(x + 24, y + 7, z + 13, this.Block6, 0, 3);
		world.setBlock(x + 25, y + 7, z + 13, this.Block6, 0, 3);
		world.setBlock(x + 26, y + 7, z + 13, this.Block6, 0, 3);
		world.setBlock(x + 27, y + 7, z + 13, this.Block6, 0, 3);
		world.setBlock(x + 28, y + 7, z + 13, this.Block6, 0, 3);
		world.setBlock(x + 29, y + 7, z + 13, this.Block6, 0, 3);
		world.setBlock(x + 30, y + 7, z + 13, this.Block6, 0, 3);
		world.setBlock(x + 31, y + 7, z + 13, this.Block6, 0, 3);
		world.setBlock(x + 32, y + 7, z + 13, this.Block6, 0, 3);
		world.setBlock(x + 33, y + 7, z + 13, this.Block18, 0, 3);
		world.setBlock(x + 34, y + 7, z + 13, this.Block18, 0, 3);
		world.setBlock(x + 35, y + 7, z + 13, Blocks.vine, 4, 3);
		world.setBlock(x + 5, y + 7, z + 14, this.Block5, 0, 3);
		world.setBlock(x + 6, y + 7, z + 14, this.Block5, 0, 3);
		world.setBlock(x + 10, y + 7, z + 14, this.Block5, 0, 3);
		world.setBlock(x + 11, y + 7, z + 14, this.Block5, 0, 3);
		world.setBlock(x + 16, y + 7, z + 14, this.Block25, 0, 3);
		world.setBlock(x + 17, y + 7, z + 14, this.Block25, 0, 3);
		world.setBlock(x + 18, y + 7, z + 14, this.Block25, 0, 3);
		world.setBlock(x + 19, y + 7, z + 14, this.Block25, 0, 3);
		world.setBlock(x + 20, y + 7, z + 14, this.Block25, 0, 3);
		world.setBlock(x + 21, y + 7, z + 14, this.Block25, 0, 3);
		world.setBlock(x + 22, y + 7, z + 14, this.Block25, 0, 3);
		world.setBlock(x + 23, y + 7, z + 14, this.Block25, 0, 3);
		world.setBlock(x + 24, y + 7, z + 14, this.Block25, 0, 3);
		world.setBlock(x + 25, y + 7, z + 14, this.Block25, 0, 3);
		world.setBlock(x + 26, y + 7, z + 14, this.Block25, 0, 3);
		world.setBlock(x + 27, y + 7, z + 14, this.Block25, 0, 3);
		world.setBlock(x + 28, y + 7, z + 14, this.Block25, 0, 3);
		world.setBlock(x + 29, y + 7, z + 14, this.Block25, 0, 3);
		world.setBlock(x + 30, y + 7, z + 14, this.Block6, 0, 3);
		world.setBlock(x + 31, y + 7, z + 14, this.Block6, 0, 3);
		world.setBlock(x + 32, y + 7, z + 14, this.Block18, 0, 3);
		world.setBlock(x + 33, y + 7, z + 14, this.Block18, 0, 3);
		world.setBlock(x + 34, y + 7, z + 14, this.Block18, 0, 3);
		world.setBlock(x + 6, y + 7, z + 15, this.Block5, 0, 3);
		world.setBlock(x + 7, y + 7, z + 15, this.Block5, 0, 3);
		world.setBlock(x + 8, y + 7, z + 15, this.Block5, 0, 3);
		world.setBlock(x + 9, y + 7, z + 15, this.Block5, 0, 3);
		world.setBlock(x + 10, y + 7, z + 15, this.Block5, 0, 3);
		world.setBlock(x + 16, y + 7, z + 15, Library.getRandomConcrete(), 0, 3);
		world.setBlock(x + 17, y + 7, z + 15, this.Block6, 0, 3);
		world.setBlock(x + 18, y + 7, z + 15, this.Block6, 0, 3);
		world.setBlock(x + 19, y + 7, z + 15, this.Block6, 0, 3);
		world.setBlock(x + 20, y + 7, z + 15, this.Block6, 0, 3);
		world.setBlock(x + 21, y + 7, z + 15, this.Block6, 0, 3);
		world.setBlock(x + 22, y + 7, z + 15, this.Block6, 0, 3);
		world.setBlock(x + 23, y + 7, z + 15, this.Block6, 0, 3);
		world.setBlock(x + 24, y + 7, z + 15, this.Block6, 0, 3);
		world.setBlock(x + 25, y + 7, z + 15, this.Block6, 0, 3);
		world.setBlock(x + 26, y + 7, z + 15, this.Block6, 0, 3);
		world.setBlock(x + 27, y + 7, z + 15, this.Block6, 0, 3);
		world.setBlock(x + 28, y + 7, z + 15, this.Block6, 0, 3);
		world.setBlock(x + 29, y + 7, z + 15, this.Block6, 0, 3);
		world.setBlock(x + 30, y + 7, z + 15, this.Block6, 0, 3);
		world.setBlock(x + 31, y + 7, z + 15, this.Block6, 0, 3);
		world.setBlock(x + 32, y + 7, z + 15, this.Block18, 0, 3);
		world.setBlock(x + 33, y + 7, z + 15, this.Block18, 0, 3);
		world.setBlock(x + 34, y + 7, z + 15, Blocks.vine, 2, 3);
		world.setBlock(x + 8, y + 7, z + 16, this.Block5, 0, 3);
		world.setBlock(x + 16, y + 7, z + 16, Library.getRandomConcrete(), 0, 3);
		world.setBlock(x + 17, y + 7, z + 16, this.Block6, 0, 3);
		world.setBlock(x + 18, y + 7, z + 16, this.Block6, 0, 3);
		world.setBlock(x + 19, y + 7, z + 16, this.Block6, 0, 3);
		world.setBlock(x + 20, y + 7, z + 16, this.Block6, 0, 3);
		world.setBlock(x + 21, y + 7, z + 16, this.Block6, 0, 3);
		world.setBlock(x + 22, y + 7, z + 16, this.Block6, 0, 3);
		world.setBlock(x + 23, y + 7, z + 16, this.Block6, 0, 3);
		world.setBlock(x + 24, y + 7, z + 16, this.Block6, 0, 3);
		world.setBlock(x + 25, y + 7, z + 16, this.Block6, 0, 3);
		world.setBlock(x + 26, y + 7, z + 16, this.Block6, 0, 3);
		world.setBlock(x + 27, y + 7, z + 16, this.Block6, 0, 3);
		world.setBlock(x + 28, y + 7, z + 16, this.Block6, 0, 3);
		world.setBlock(x + 29, y + 7, z + 16, this.Block6, 0, 3);
		world.setBlock(x + 30, y + 7, z + 16, this.Block6, 0, 3);
		world.setBlock(x + 31, y + 7, z + 16, this.Block18, 0, 3);
		world.setBlock(x + 32, y + 7, z + 16, this.Block18, 0, 3);
		world.setBlock(x + 33, y + 7, z + 16, this.Block18, 0, 3);
		world.setBlock(x + 34, y + 7, z + 16, Blocks.vine, 2, 3);
		world.setBlock(x + 8, y + 7, z + 17, this.Block5, 0, 3);
		world.setBlock(x + 16, y + 7, z + 17, Library.getRandomConcrete(), 0, 3);
		world.setBlock(x + 17, y + 7, z + 17, this.Block6, 0, 3);
		world.setBlock(x + 18, y + 7, z + 17, this.Block6, 0, 3);
		world.setBlock(x + 19, y + 7, z + 17, this.Block6, 0, 3);
		world.setBlock(x + 20, y + 7, z + 17, this.Block6, 0, 3);
		world.setBlock(x + 21, y + 7, z + 17, this.Block6, 0, 3);
		world.setBlock(x + 22, y + 7, z + 17, this.Block6, 0, 3);
		world.setBlock(x + 23, y + 7, z + 17, this.Block6, 0, 3);
		world.setBlock(x + 24, y + 7, z + 17, this.Block6, 0, 3);
		world.setBlock(x + 25, y + 7, z + 17, this.Block6, 0, 3);
		world.setBlock(x + 26, y + 7, z + 17, this.Block6, 0, 3);
		world.setBlock(x + 27, y + 7, z + 17, this.Block6, 0, 3);
		world.setBlock(x + 28, y + 7, z + 17, this.Block6, 0, 3);
		world.setBlock(x + 29, y + 7, z + 17, this.Block6, 0, 3);
		world.setBlock(x + 30, y + 7, z + 17, this.Block6, 0, 3);
		world.setBlock(x + 31, y + 7, z + 17, this.Block18, 0, 3);
		world.setBlock(x + 32, y + 7, z + 17, this.Block18, 0, 3);
		world.setBlock(x + 33, y + 7, z + 17, Blocks.vine, 2, 3);
		world.setBlock(x + 8, y + 7, z + 18, this.Block5, 0, 3);
		world.setBlock(x + 16, y + 7, z + 18, Library.getRandomConcrete(), 0, 3);
		world.setBlock(x + 17, y + 7, z + 18, Library.getRandomConcrete(), 0, 3);
		world.setBlock(x + 18, y + 7, z + 18, Library.getRandomConcrete(), 0, 3);
		world.setBlock(x + 19, y + 7, z + 18, Library.getRandomConcrete(), 0, 3);
		world.setBlock(x + 20, y + 7, z + 18, Library.getRandomConcrete(), 0, 3);
		world.setBlock(x + 21, y + 7, z + 18, Library.getRandomConcrete(), 0, 3);
		world.setBlock(x + 22, y + 7, z + 18, Library.getRandomConcrete(), 0, 3);
		world.setBlock(x + 23, y + 7, z + 18, Library.getRandomConcrete(), 0, 3);
		world.setBlock(x + 24, y + 7, z + 18, Library.getRandomConcrete(), 0, 3);
		world.setBlock(x + 25, y + 7, z + 18, Library.getRandomConcrete(), 0, 3);
		world.setBlock(x + 26, y + 7, z + 18, Library.getRandomConcrete(), 0, 3);
		world.setBlock(x + 27, y + 7, z + 18, Library.getRandomConcrete(), 0, 3);
		world.setBlock(x + 28, y + 7, z + 18, Library.getRandomConcrete(), 0, 3);
		world.setBlock(x + 29, y + 7, z + 18, Library.getRandomConcrete(), 0, 3);
		world.setBlock(x + 30, y + 7, z + 18, Library.getRandomConcrete(), 0, 3);
		world.setBlock(x + 31, y + 7, z + 18, Library.getRandomConcrete(), 0, 3);
		world.setBlock(x + 32, y + 7, z + 18, Library.getRandomConcrete(), 0, 3);
		world.setBlock(x + 33, y + 7, z + 18, Library.getRandomConcrete(), 0, 3);
		world.setBlock(x + 8, y + 7, z + 19, this.Block5, 0, 3);
		world.setBlock(x + 8, y + 7, z + 20, this.Block5, 0, 3);
		world.setBlock(x + 6, y + 7, z + 21, this.Block15, 0, 3);
		world.setBlock(x + 7, y + 7, z + 21, this.Block15, 0, 3);
		world.setBlock(x + 8, y + 7, z + 21, this.Block15, 0, 3);
		world.setBlock(x + 9, y + 7, z + 21, this.Block15, 0, 3);
		world.setBlock(x + 10, y + 7, z + 21, this.Block15, 0, 3);
		world.setBlock(x + 5, y + 7, z + 22, this.Block15, 0, 3);
		world.setBlock(x + 6, y + 7, z + 22, this.Block7, 0, 3);
		world.setBlock(x + 7, y + 7, z + 22, this.Block7, 0, 3);
		world.setBlock(x + 8, y + 7, z + 22, this.Block7, 0, 3);
		world.setBlock(x + 9, y + 7, z + 22, this.Block7, 0, 3);
		world.setBlock(x + 10, y + 7, z + 22, this.Block7, 0, 3);
		world.setBlock(x + 11, y + 7, z + 22, this.Block15, 0, 3);
		world.setBlock(x + 4, y + 7, z + 23, this.Block15, 0, 3);
		world.setBlock(x + 5, y + 7, z + 23, this.Block7, 0, 3);
		world.setBlock(x + 7, y + 7, z + 23, ModBlocks.fence_metal, 0, 3);
		world.setBlock(x + 8, y + 7, z + 23, this.Block7, 0, 3);
		world.setBlock(x + 11, y + 7, z + 23, this.Block7, 0, 3);
		world.setBlock(x + 12, y + 7, z + 23, this.Block15, 0, 3);
		world.setBlock(x + 4, y + 7, z + 24, this.Block15, 0, 3);
		world.setBlock(x + 5, y + 7, z + 24, this.Block7, 0, 3);
		world.setBlock(x + 8, y + 7, z + 24, this.Block7, 0, 3);
		world.setBlock(x + 9, y + 7, z + 24, ModBlocks.fence_metal, 0, 3);
		world.setBlock(x + 11, y + 7, z + 24, this.Block7, 0, 3);
		world.setBlock(x + 12, y + 7, z + 24, this.Block15, 0, 3);
		world.setBlock(x + 4, y + 7, z + 25, this.Block15, 0, 3);
		world.setBlock(x + 5, y + 7, z + 25, this.Block7, 0, 3);
		world.setBlock(x + 7, y + 7, z + 25, ModBlocks.fence_metal, 0, 3);
		world.setBlock(x + 8, y + 7, z + 25, this.Block7, 0, 3);
		world.setBlock(x + 9, y + 7, z + 25, ModBlocks.fence_metal, 0, 3);
		world.setBlock(x + 11, y + 7, z + 25, this.Block7, 0, 3);
		world.setBlock(x + 12, y + 7, z + 25, this.Block15, 0, 3);
		world.setBlock(x + 4, y + 7, z + 26, this.Block15, 0, 3);
		world.setBlock(x + 5, y + 7, z + 26, this.Block7, 0, 3);
		world.setBlock(x + 8, y + 7, z + 26, this.Block7, 0, 3);
		world.setBlock(x + 11, y + 7, z + 26, this.Block7, 0, 3);
		world.setBlock(x + 12, y + 7, z + 26, this.Block15, 0, 3);
		world.setBlock(x + 4, y + 7, z + 27, this.Block15, 0, 3);
		world.setBlock(x + 5, y + 7, z + 27, this.Block7, 0, 3);
		world.setBlock(x + 7, y + 7, z + 27, ModBlocks.fence_metal, 0, 3);
		world.setBlock(x + 8, y + 7, z + 27, this.Block7, 0, 3);
		world.setBlock(x + 9, y + 7, z + 27, ModBlocks.fence_metal, 0, 3);
		world.setBlock(x + 11, y + 7, z + 27, this.Block7, 0, 3);
		world.setBlock(x + 12, y + 7, z + 27, this.Block15, 0, 3);
		world.setBlock(x + 5, y + 7, z + 28, this.Block15, 0, 3);
		world.setBlock(x + 6, y + 7, z + 28, this.Block7, 0, 3);
		world.setBlock(x + 7, y + 7, z + 28, this.Block7, 0, 3);
		world.setBlock(x + 8, y + 7, z + 28, this.Block7, 0, 3);
		world.setBlock(x + 9, y + 7, z + 28, this.Block7, 0, 3);
		world.setBlock(x + 10, y + 7, z + 28, this.Block7, 0, 3);
		world.setBlock(x + 11, y + 7, z + 28, this.Block15, 0, 3);
		world.setBlock(x + 6, y + 7, z + 29, this.Block15, 0, 3);
		world.setBlock(x + 7, y + 7, z + 29, this.Block15, 0, 3);
		world.setBlock(x + 8, y + 7, z + 29, this.Block15, 0, 3);
		world.setBlock(x + 9, y + 7, z + 29, this.Block15, 0, 3);
		world.setBlock(x + 10, y + 7, z + 29, this.Block15, 0, 3);
		world.setBlock(x + 16, y + 8, z + 6, Library.getRandomConcrete(), 0, 3);
		world.setBlock(x + 17, y + 8, z + 6, Library.getRandomConcrete(), 0, 3);
		world.setBlock(x + 18, y + 8, z + 6, Library.getRandomConcrete(), 0, 3);
		world.setBlock(x + 19, y + 8, z + 6, Library.getRandomConcrete(), 0, 3);
		world.setBlock(x + 20, y + 8, z + 6, Library.getRandomConcrete(), 0, 3);
		world.setBlock(x + 21, y + 8, z + 6, Library.getRandomConcrete(), 0, 3);
		world.setBlock(x + 23, y + 8, z + 6, Library.getRandomConcrete(), 0, 3);
		world.setBlock(x + 25, y + 8, z + 6, Library.getRandomConcrete(), 0, 3);
		world.setBlock(x + 26, y + 8, z + 6, Library.getRandomConcrete(), 0, 3);
		world.setBlock(x + 27, y + 8, z + 6, Library.getRandomConcrete(), 0, 3);
		world.setBlock(x + 28, y + 8, z + 6, Library.getRandomConcrete(), 0, 3);
		world.setBlock(x + 29, y + 8, z + 6, Library.getRandomConcrete(), 0, 3);
		world.setBlock(x + 30, y + 8, z + 6, Library.getRandomConcrete(), 0, 3);
		world.setBlock(x + 31, y + 8, z + 6, Library.getRandomConcrete(), 0, 3);
		world.setBlock(x + 32, y + 8, z + 6, Library.getRandomConcrete(), 0, 3);
		world.setBlock(x + 33, y + 8, z + 6, Library.getRandomConcrete(), 0, 3);
		world.setBlock(x + 34, y + 8, z + 6, Library.getRandomConcrete(), 0, 3);
		world.setBlock(x + 35, y + 8, z + 6, Library.getRandomConcrete(), 0, 3);
		world.setBlock(x + 36, y + 8, z + 6, Library.getRandomConcrete(), 0, 3);
		world.setBlock(x + 16, y + 8, z + 7, Library.getRandomConcrete(), 0, 3);
		world.setBlock(x + 19, y + 8, z + 7, ModBlocks.fence_metal, 0, 3);
		world.setBlock(x + 16, y + 8, z + 8, Library.getRandomConcrete(), 0, 3);
		world.setBlock(x + 19, y + 8, z + 8, ModBlocks.fence_metal, 0, 3);
		world.setBlock(x + 37, y + 8, z + 8, Library.getRandomConcrete(), 0, 3);
		world.setBlock(x + 6, y + 8, z + 9, this.Block5, 0, 3);
		world.setBlock(x + 7, y + 8, z + 9, this.Block5, 0, 3);
		world.setBlock(x + 8, y + 8, z + 9, this.Block5, 0, 3);
		world.setBlock(x + 9, y + 8, z + 9, this.Block5, 0, 3);
		world.setBlock(x + 10, y + 8, z + 9, this.Block5, 0, 3);
		world.setBlock(x + 16, y + 8, z + 9, Library.getRandomConcrete(), 0, 3);
		world.setBlock(x + 19, y + 8, z + 9, ModBlocks.fence_metal, 0, 3);
		world.setBlock(x + 23, y + 8, z + 9, this.Block25, 0, 3);
		world.setBlock(x + 24, y + 8, z + 9, this.Block25, 0, 3);
		world.setBlock(x + 25, y + 8, z + 9, this.Block28, 3, 3);
		world.setBlock(x + 26, y + 8, z + 9, this.Block25, 0, 3);
		world.setBlock(x + 27, y + 8, z + 9, this.Block25, 0, 3);
		world.setBlock(x + 28, y + 8, z + 9, this.Block28, 3, 3);
		world.setBlock(x + 29, y + 8, z + 9, this.Block25, 0, 3);
		world.setBlock(x + 30, y + 8, z + 9, this.Block25, 0, 3);
		world.setBlock(x + 31, y + 8, z + 9, this.Block29, 3, 3);
		world.setBlock(x + 37, y + 8, z + 9, Library.getRandomConcrete(), 0, 3);
		world.setBlock(x + 5, y + 8, z + 10, this.Block5, 0, 3);
		world.setBlock(x + 6, y + 8, z + 10, this.Block5, 0, 3);
		world.setBlock(x + 7, y + 8, z + 10, this.Block11, 0, 3);
		world.setBlock(x + 8, y + 8, z + 10, this.Block5, 0, 3);
		world.setBlock(x + 9, y + 8, z + 10, this.Block11, 0, 3);
		world.setBlock(x + 10, y + 8, z + 10, this.Block5, 0, 3);
		world.setBlock(x + 11, y + 8, z + 10, this.Block5, 0, 3);
		world.setBlock(x + 16, y + 8, z + 10, Library.getRandomConcrete(), 0, 3);
		world.setBlock(x + 37, y + 8, z + 10, Library.getRandomConcrete(), 0, 3);
		world.setBlock(x + 5, y + 8, z + 11, this.Block5, 0, 3);
		world.setBlock(x + 6, y + 8, z + 11, this.Block11, 0, 3);
		world.setBlock(x + 10, y + 8, z + 11, this.Block11, 0, 3);
		world.setBlock(x + 11, y + 8, z + 11, this.Block5, 0, 3);
		world.setBlock(x + 12, y + 8, z + 11, ModBlocks.fence_metal, 0, 3);
		world.setBlock(x + 14, y + 8, z + 11, ModBlocks.fence_metal, 0, 3);
		world.setBlock(x + 15, y + 8, z + 11, ModBlocks.fence_metal, 0, 3);
		world.setBlock(x + 16, y + 8, z + 11, Library.getRandomConcrete(), 0, 3);
		world.setBlock(x + 19, y + 8, z + 11, ModBlocks.fence_metal, 0, 3);
		world.setBlock(x + 37, y + 8, z + 11, Blocks.gravel, 0, 3);
		world.setBlock(x + 5, y + 8, z + 12, this.Block5, 0, 3);
		world.setBlock(x + 6, y + 8, z + 12, this.Block5, 0, 3);
		world.setBlock(x + 8, y + 8, z + 12, this.Block25, 0, 3);
		world.setBlock(x + 10, y + 8, z + 12, this.Block5, 0, 3);
		world.setBlock(x + 11, y + 8, z + 12, this.Block5, 0, 3);
		world.setBlock(x + 16, y + 8, z + 12, Library.getRandomConcrete(), 0, 3);
		world.setBlock(x + 19, y + 8, z + 12, ModBlocks.fence_metal, 0, 3);
		world.setBlock(x + 5, y + 8, z + 13, this.Block5, 0, 3);
		world.setBlock(x + 6, y + 8, z + 13, this.Block11, 0, 3);
		world.setBlock(x + 10, y + 8, z + 13, this.Block11, 0, 3);
		world.setBlock(x + 11, y + 8, z + 13, this.Block5, 0, 3);
		world.setBlock(x + 12, y + 8, z + 13, ModBlocks.fence_metal, 0, 3);
		world.setBlock(x + 13, y + 8, z + 13, ModBlocks.fence_metal, 0, 3);
		world.setBlock(x + 14, y + 8, z + 13, ModBlocks.fence_metal, 0, 3);
		world.setBlock(x + 16, y + 8, z + 13, Library.getRandomConcrete(), 0, 3);
		world.setBlock(x + 33, y + 8, z + 13, this.Block13, 5, 3);
		world.setBlock(x + 5, y + 8, z + 14, this.Block5, 0, 3);
		world.setBlock(x + 6, y + 8, z + 14, this.Block5, 0, 3);
		world.setBlock(x + 7, y + 8, z + 14, this.Block11, 0, 3);
		world.setBlock(x + 8, y + 8, z + 14, this.Block5, 0, 3);
		world.setBlock(x + 9, y + 8, z + 14, this.Block11, 0, 3);
		world.setBlock(x + 10, y + 8, z + 14, this.Block5, 0, 3);
		world.setBlock(x + 11, y + 8, z + 14, this.Block5, 0, 3);
		world.setBlock(x + 16, y + 8, z + 14, Library.getRandomConcrete(), 0, 3);
		world.setBlock(x + 22, y + 8, z + 14, this.Block5, 0, 3);
		world.setBlock(x + 23, y + 8, z + 14, this.Block25, 0, 3);
		world.setBlock(x + 27, y + 8, z + 14, this.Block5, 0, 3);
		world.setBlock(x + 28, y + 8, z + 14, this.Block25, 0, 3);
		world.setBlock(x + 29, y + 8, z + 14, this.Block5, 0, 3);
		world.setBlock(x + 32, y + 8, z + 14, this.Block8, 5, 3);
		world.setBlock(x + 6, y + 8, z + 15, this.Block5, 0, 3);
		world.setBlock(x + 7, y + 8, z + 15, this.Block5, 0, 3);
		world.setBlock(x + 8, y + 8, z + 15, this.Block5, 0, 3);
		world.setBlock(x + 9, y + 8, z + 15, this.Block5, 0, 3);
		world.setBlock(x + 10, y + 8, z + 15, this.Block5, 0, 3);
		world.setBlock(x + 16, y + 8, z + 15, Library.getRandomConcrete(), 0, 3);
		world.setBlock(x + 22, y + 8, z + 15, this.Block5, 0, 3);
		world.setBlock(x + 23, y + 8, z + 15, this.Block5, 0, 3);
		world.setBlock(x + 24, y + 8, z + 15, this.Block5, 0, 3);
		world.setBlock(x + 27, y + 8, z + 15, this.Block5, 0, 3);
		world.setBlock(x + 28, y + 8, z + 15, this.Block5, 0, 3);
		world.setBlock(x + 29, y + 8, z + 15, this.Block5, 0, 3);
		world.setBlock(x + 30, y + 8, z + 15, this.Block8, 2, 3);
		world.setBlock(x + 31, y + 8, z + 15, this.Block8, 3, 3);
		world.setBlock(x + 7, y + 8, z + 16, ModBlocks.fence_metal, 0, 3);
		world.setBlock(x + 9, y + 8, z + 16, ModBlocks.fence_metal, 0, 3);
		world.setBlock(x + 16, y + 8, z + 16, Library.getRandomConcrete(), 0, 3);
		world.setBlock(x + 22, y + 8, z + 16, this.Block5, 0, 3);
		world.setBlock(x + 23, y + 8, z + 16, this.Block5, 0, 3);
		world.setBlock(x + 24, y + 8, z + 16, this.Block5, 0, 3);
		world.setBlock(x + 27, y + 8, z + 16, this.Block5, 0, 3);
		world.setBlock(x + 28, y + 8, z + 16, this.Block5, 0, 3);
		world.setBlock(x + 29, y + 8, z + 16, this.Block5, 0, 3);
		world.setBlock(x + 7, y + 8, z + 17, ModBlocks.fence_metal, 0, 3);
		world.setBlock(x + 16, y + 8, z + 17, Library.getRandomConcrete(), 0, 3);
		world.setBlock(x + 7, y + 8, z + 18, ModBlocks.fence_metal, 0, 3);
		world.setBlock(x + 9, y + 8, z + 18, ModBlocks.fence_metal, 0, 3);
		world.setBlock(x + 16, y + 8, z + 18, Library.getRandomConcrete(), 0, 3);
		world.setBlock(x + 17, y + 8, z + 18, Library.getRandomConcrete(), 0, 3);
		world.setBlock(x + 18, y + 8, z + 18, Library.getRandomConcrete(), 0, 3);
		world.setBlock(x + 19, y + 8, z + 18, Library.getRandomConcrete(), 0, 3);
		world.setBlock(x + 20, y + 8, z + 18, Library.getRandomConcrete(), 0, 3);
		world.setBlock(x + 21, y + 8, z + 18, Library.getRandomConcrete(), 0, 3);
		world.setBlock(x + 22, y + 8, z + 18, Library.getRandomConcrete(), 0, 3);
		world.setBlock(x + 23, y + 8, z + 18, Library.getRandomConcrete(), 0, 3);
		world.setBlock(x + 24, y + 8, z + 18, Library.getRandomConcrete(), 0, 3);
		world.setBlock(x + 25, y + 8, z + 18, Library.getRandomConcrete(), 0, 3);
		world.setBlock(x + 26, y + 8, z + 18, Library.getRandomConcrete(), 0, 3);
		world.setBlock(x + 27, y + 8, z + 18, Library.getRandomConcrete(), 0, 3);
		world.setBlock(x + 28, y + 8, z + 18, Library.getRandomConcrete(), 0, 3);
		world.setBlock(x + 29, y + 8, z + 18, Library.getRandomConcrete(), 0, 3);
		world.setBlock(x + 30, y + 8, z + 18, Library.getRandomConcrete(), 0, 3);
		world.setBlock(x + 31, y + 8, z + 18, Library.getRandomConcrete(), 0, 3);
		world.setBlock(x + 32, y + 8, z + 18, Library.getRandomConcrete(), 0, 3);
		world.setBlock(x + 33, y + 8, z + 18, Blocks.gravel, 0, 3);
		world.setBlock(x + 9, y + 8, z + 19, ModBlocks.fence_metal, 0, 3);
		world.setBlock(x + 7, y + 8, z + 21, ModBlocks.fence_metal, 0, 3);
		world.setBlock(x + 9, y + 8, z + 21, ModBlocks.fence_metal, 0, 3);
		world.setBlock(x + 6, y + 8, z + 22, this.Block15, 0, 3);
		world.setBlock(x + 7, y + 8, z + 22, this.Block15, 0, 3);
		world.setBlock(x + 8, y + 8, z + 22, Blocks.iron_door, 1, 3);
        ItemDoor.placeDoorBlock(world, x + 8, y + 8, z + 22, 1, Blocks.iron_door);
		world.setBlock(x + 9, y + 8, z + 22, this.Block15, 0, 3);
		world.setBlock(x + 10, y + 8, z + 22, this.Block15, 0, 3);
		world.setBlock(x + 5, y + 8, z + 23, this.Block15, 0, 3);
		world.setBlock(x + 7, y + 8, z + 23, ModBlocks.fence_metal, 0, 3);
		world.setBlock(x + 11, y + 8, z + 23, this.Block15, 0, 3);
		world.setBlock(x + 5, y + 8, z + 24, this.Block15, 0, 3);
		world.setBlock(x + 9, y + 8, z + 24, ModBlocks.fence_metal, 0, 3);
		world.setBlock(x + 11, y + 8, z + 24, this.Block15, 0, 3);
		world.setBlock(x + 5, y + 8, z + 25, this.Block15, 0, 3);
		world.setBlock(x + 9, y + 8, z + 25, ModBlocks.fence_metal, 0, 3);
		world.setBlock(x + 11, y + 8, z + 25, this.Block15, 0, 3);
		world.setBlock(x + 5, y + 8, z + 26, this.Block15, 0, 3);
		world.setBlock(x + 11, y + 8, z + 26, this.Block15, 0, 3);
		world.setBlock(x + 5, y + 8, z + 27, this.Block15, 0, 3);
		world.setBlock(x + 7, y + 8, z + 27, ModBlocks.fence_metal, 0, 3);
		world.setBlock(x + 9, y + 8, z + 27, ModBlocks.fence_metal, 0, 3);
		world.setBlock(x + 11, y + 8, z + 27, this.Block15, 0, 3);
		world.setBlock(x + 6, y + 8, z + 28, this.Block15, 0, 3);
		world.setBlock(x + 7, y + 8, z + 28, this.Block15, 0, 3);
		world.setBlock(x + 8, y + 8, z + 28, this.Block15, 0, 3);
		world.setBlock(x + 9, y + 8, z + 28, this.Block15, 0, 3);
		world.setBlock(x + 10, y + 8, z + 28, this.Block15, 0, 3);
		world.setBlock(x + 7, y + 9, z + 10, this.Block11, 0, 3);
